Workbook
Name _________RC511NAC_RC511NX_List: #REF!
Name ________EXP1: #REF!
Name ________LTL1: #REF!
Name ________LTL2: #REF!
Name ________LTL3: #REF!
Name ________LTL4: #REF!
Name ________LTL5: #REF!
Name ________LTL6: #REF!
Name ________RC511NAC_RC511NX_List: #REF!
Name _______EXP1: #REF!
Name _______LTL1: #REF!
Name _______LTL2: #REF!
Name _______LTL3: #REF!
Name _______LTL4: #REF!
Name _______LTL5: #REF!
Name _______LTL6: #REF!
Name _______RC511NAC_RC511NX_List: #REF!
Name ______EXP1: #REF!
Name ______RC511NAC_RC511NX_List: #REF!
Name _____RC511NAC_RC511NX_List: #REF!
Name _____SCE1: #REF!
Name _____SCE2: #REF!
Name _____SCE3: #REF!
Name _____SCE4: #REF!
Name ____BUN1: #REF!
Name ____GPR1: #REF!
Name ____GPR2: #REF!
Name ____GPR3: #REF!
Name ____GPR4: #REF!
Name ____GPR5: #REF!
Name ____GPR6: #REF!
Name ____LA1: #REF!
Name ____RC511NAC_RC511NX_List: #REF!
Name ____REF1: #N/A
Name ____REF2: #N/A
Name ____SCE1: #REF!
Name ____SCE2: #REF!
Name ____SCE3: #REF!
Name ____SCE4: #REF!
Name ____SF1: #REF!
Name ____SF2: #REF!
Name ____SF3: #REF!
Name ____SF4: #REF!
Name ____SF5: #REF!
Name ___ASS1: #N/A
Name ___ASS2: #N/A
Name ___ass3: #N/A
Name ___AVI1: #N/A
Name ___BUN1: #REF!
Name ___CAM96: #REF!
Name ___CAM97: #REF!
Name ___CAM9710: #REF!
Name ___GPR1: #REF!
Name ___GPR2: #REF!
Name ___GPR3: #REF!
Name ___GPR4: #REF!
Name ___GPR5: #REF!
Name ___GPR6: #REF!
Name ___GSF2: #N/A
Name ___INF1: #N/A

Sheet Assumption
B2: Project SF | D2: ='Rent Roll'!D21 -> 39150 | F2: Sources and Uses
B3: Analysis Start | D3: 44256 | G3: At Close | H3: Future Funding | I3: Fully Funded
B4: Hold Period | D4: 60 | F4: Senior Loan | G4: =D23 -> 13978444 | H4: =D24 -> 4080225.1 | I4: =SUM(G4:H4) -> 18058669
F5: Equity
B6: Acquisition | F6: LP Equity (90%) | G6: =MAX(G19-G4-G8,0)*90% -> 10997730 | H6: =MAX(H19-H4-H8,0)*90% -> 1304389.1 | I6: =SUM(G6:H6) -> 12302119
B7: NOI | D7: 1466676 | F7: GP Equity (10%) | G7: =MAX(G19-G4-G8,0)*10% -> 1221969.9 | H7: =MAX(H19-H4-H8,0)*10% -> 144932.12 | I7: =SUM(G7:H7) -> 1366902.1
B8: Cap Rate | D8: 0.0575 | F8: CF from Operations / Sale | G8: =G18 -> 0 | H8: =H18 -> 29554386 | I8: =SUM(G8:H8) -> 29554386
B9: Purchase Price | D9: 25507409 | F9: Total Sources | G9: =SUM(G4:G8) -> 26198144 | H9: =SUM(H4:H8) -> 35083932 | I9: =SUM(I4:I8) -> 61282076
B10: TI/LC | D10: 4080225.1
B11: Closing Cost | C11: 0.02 | D11: 510148.17 | F11: Uses
B12: Total Going in Basis | D12: 30097782 | F12: Acquisition | G12: =D9 -> 25507409 | H12: =0 -> 0 | I12: =SUM(G12:H12) -> 25507409
F13: CapEX / TI / LC | G13: =0 -> 0 | H13: =-SUM(Proforma!F13:BN13) -> 5529546.3 | I13: =SUM(G13:H13) -> 5529546.3
B14: Exit Assumption | F14: Closing Costs | G14: =D11 -> 510148.17 | H14: =0 -> 0 | I14: =SUM(G14:H14) -> 510148.17
B15: Take out cap rate | D15: 0.06 | F15: Loan / Financing Fees | G15: =D26 -> 180586.69 | H15: =0 -> 0 | I15: =SUM(G15:H15) -> 180586.69
B16: Forward NOI | D16: =SUM(OFFSET('Cash Flow'!$G$33,0,$D$4,1,12)) -> 2682760.4 | F16: Capex / Interest Reserve | G16: 0 | H16: 0 | I16: =SUM(G16:H16) -> 0
B17: Exit Value | D17: =D16/D15 -> 44712673 | F17: Working Capital / Op Reserve | G17: 0 | H17: 0 | I17: =SUM(G17:H17) -> 0
B18: Sales Cost | C18: 0.02 | D18: =D17*C18 -> 894253.46 | F18: Equity Distributions | G18: =MAX(0,Proforma!F63) -> 0 | H18: =SUM(Proforma!G63:BN63) -> 29554386 | I18: =SUM(G18:H18) -> 29554386
F19: Total Uses | G19: =SUM(G12:G18) -> 26198144 | H19: =SUM(H12:H18) -> 35083932 | I19: =SUM(I12:I18) -> 61282076
F20: Sources / Uses Check | G20: =G9-G19 -> 0 | H20: =H9-H19 -> 0 | I20: =I9-I19 -> 0
B21: Debt Assumption
B22: LTV | D22: 0.6
B23: Initial Funding | D23: =D25-D24 -> 13978444
B24: Future Funding | D24: =D10 -> 4080225.1
B25: Total Debt | D25: =D12*D22 -> 18058669
B26: Fees | C26: 0.01 | D26: =D25*C26 -> 180586.69
B27: Amortization | D27: I/O
B28: Term | D28: 36
B29: 1st Extension | D29: 36
B30: Extension Fee | D30: 75000
B31: 2nd Extension | D31: 48
B32: Extension Fee | D32: 75000
B33: DSCR | D33: 1.25
B34: Debt Yield | D34: 8
B35: Interest Rate Spread | D35: 0.035
B36: Floor | D36: 0.0375
B37: Index | D37: SOFR

Sheet Proforma
B2: Proforma
G3: Actual | H3: Actual | I3: Actual | J3: Actual | K3: Actual | L3: Actual | M3: Actual | N3: Actual | O3: Actual | P3: Actual | Q3: Forecast | R3: Forecast | S3: Forecast | T3: Forecast | U3: Forecast | V3: Forecast | W3: Forecast | X3: Forecast | Y3: Forecast | Z3: Forecast | AA3: Forecast | AB3: Forecast | AC3: Forecast | AD3: Forecast | AE3: Forecast | AF3: Forecast | AG3: Forecast | AH3: Forecast | AI3: Forecast | AJ3: Forecast | AK3: Forecast | AL3: Forecast | AM3: Forecast | AN3: Forecast | AO3: Forecast | AP3: Forecast | AQ3: Forecast | AR3: Forecast | AS3: Forecast | AT3: Forecast | AU3: Forecast | AV3: Forecast | AW3: Forecast | AX3: Forecast | AY3: Forecast | AZ3: Forecast | BA3: Forecast | BB3: Forecast | BC3: Forecast | BD3: Forecast | BE3: Forecast | BF3: Forecast | BG3: Forecast | BH3: Forecast | BI3: Forecast | BJ3: Forecast | BK3: Forecast | BL3: Forecast | BM3: Forecast | BN3: Forecast | BO3: *
B4: Year | F4: =IF(F$5="","",ROUNDUP(F$5/12,0)) -> 0 | G4: =IF(G$5="","",ROUNDUP(G$5/12,0)) -> 1 | H4: =IF(H$5="","",ROUNDUP(H$5/12,0)) -> 1 | I4: =IF(I$5="","",ROUNDUP(I$5/12,0)) -> 1 | J4: =IF(J$5="","",ROUNDUP(J$5/12,0)) -> 1 | K4: =IF(K$5="","",ROUNDUP(K$5/12,0)) -> 1 | L4: =IF(L$5="","",ROUNDUP(L$5/12,0)) -> 1 | M4: =IF(M$5="","",ROUNDUP(M$5/12,0)) -> 1 | ... BN4: =IF(BN$5="","",ROUNDUP(BN$5/12,0)) -> 5
B5: Month | F5: 0 | G5: =IF(F5>=Assumption!$D$4,"",F5+1) -> 1 | H5: =IF(G5>=Assumption!$D$4,"",G5+1) -> 2 | I5: =IF(H5>=Assumption!$D$4,"",H5+1) -> 3 | J5: =IF(I5>=Assumption!$D$4,"",I5+1) -> 4 | K5: =IF(J5>=Assumption!$D$4,"",J5+1) -> 5 | L5: =IF(K5>=Assumption!$D$4,"",K5+1) -> 6 | M5: =IF(L5>=Assumption!$D$4,"",L5+1) -> 7 | N5: =IF(M5>=Assumption!$D$4,"",M5+1) -> 8 | ... BN5: =IF(BM5>=Assumption!$D$4,"",BM5+1) -> 60
B6: Date | F6: =Assumption!$D$3 -> 44256 | G6: =IF(G$5="","",EOMONTH($F$6,G$5-1)) -> 44286 | H6: =IF(H$5="","",EOMONTH($F$6,H$5-1)) -> 44316 | I6: =IF(I$5="","",EOMONTH($F$6,I$5-1)) -> 44347 | J6: =IF(J$5="","",EOMONTH($F$6,J$5-1)) -> 44377 | K6: =IF(K$5="","",EOMONTH($F$6,K$5-1)) -> 44408 | L6: =IF(L$5="","",EOMONTH($F$6,L$5-1)) -> 44439 | M6: =IF(M$5="","",EOMONTH($F$6,M$5-1)) -> 44469 | N6: =IF(N$5="","",EOMONTH($F$6,N$5-1)) -> 44500 | ... BN6: =IF(BN$5="","",EOMONTH($F$6,BN$5-1)) -> 46081
B8: Acquisition | F8: =-Assumption!$D$9 -> -25507409 | G8: =IF(G$5="","",0) -> 0 | H8: =IF(H$5="","",0) -> 0 | I8: =IF(I$5="","",0) -> 0 | J8: =IF(J$5="","",0) -> 0 | K8: =IF(K$5="","",0) -> 0 | L8: =IF(L$5="","",0) -> 0 | M8: =IF(M$5="","",0) -> 0 | N8: =IF(N$5="","",0) -> 0 | ... BN8: =IF(BN$5="","",0) -> 0
B10: LEASING & CAPITAL COSTS
B11: Tenant Improvements | F11: =IF(F$5="","",INDEX('Cash Flow'!$F$36:$BZ$36,1,MATCH(F$5,'Cash Flow'!$F$5:$BZ$5,0))) -> 0 | G11: =IF(G$5="","",INDEX('Cash Flow'!$F$36:$BZ$36,1,MATCH(G$5,'Cash Flow'!$F$5:$BZ$5,0))) -> 0 | H11: =IF(H$5="","",INDEX('Cash Flow'!$F$36:$BZ$36,1,MATCH(H$5,'Cash Flow'!$F$5:$BZ$5,0))) -> 0 | I11: =IF(I$5="","",INDEX('Cash Flow'!$F$36:$BZ$36,1,MATCH(I$5,'Cash Flow'!$F$5:$BZ$5,0))) -> 0 | J11: =IF(J$5="","",INDEX('Cash Flow'!$F$36:$BZ$36,1,MATCH(J$5,'Cash Flow'!$F$5:$BZ$5,0))) -> 0 | K11: =IF(K$5="","",INDEX('Cash Flow'!$F$36:$BZ$36,1,MATCH(K$5,'Cash Flow'!$F$5:$BZ$5,0))) -> 0 | L11: =IF(L$5="","",INDEX('Cash Flow'!$F$36:$BZ$36,1,MATCH(L$5,'Cash Flow'!$F$5:$BZ$5,0))) -> 0 | M11: =IF(M$5="","",INDEX('Cash Flow'!$F$36:$BZ$36,1,MATCH(M$5,'Cash Flow'!$F$5:$BZ$5,0))) -> 0 | ... BN11: =IF(BN$5="","",INDEX('Cash Flow'!$F$36:$BZ$36,1,MATCH(BN$5,'Cash Flow'!$F$5:$BZ$5,0))) -> 0
B12: Leasing Commissions | F12: =IF(F$5="","",INDEX('Cash Flow'!$F$37:$BZ$37,1,MATCH(F$5,'Cash Flow'!$F$5:$BZ$5,0))) -> 0 | G12: =IF(G$5="","",INDEX('Cash Flow'!$F$37:$BZ$37,1,MATCH(G$5,'Cash Flow'!$F$5:$BZ$5,0))) -> 0 | H12: =IF(H$5="","",INDEX('Cash Flow'!$F$37:$BZ$37,1,MATCH(H$5,'Cash Flow'!$F$5:$BZ$5,0))) -> 0 | I12: =IF(I$5="","",INDEX('Cash Flow'!$F$37:$BZ$37,1,MATCH(I$5,'Cash Flow'!$F$5:$BZ$5,0))) -> 0 | J12: =IF(J$5="","",INDEX('Cash Flow'!$F$37:$BZ$37,1,MATCH(J$5,'Cash Flow'!$F$5:$BZ$5,0))) -> 0 | K12: =IF(K$5="","",INDEX('Cash Flow'!$F$37:$BZ$37,1,MATCH(K$5,'Cash Flow'!$F$5:$BZ$5,0))) -> 0 | L12: =IF(L$5="","",INDEX('Cash Flow'!$F$37:$BZ$37,1,MATCH(L$5,'Cash Flow'!$F$5:$BZ$5,0))) -> 0 | M12: =IF(M$5="","",INDEX('Cash Flow'!$F$37:$BZ$37,1,MATCH(M$5,'Cash Flow'!$F$5:$BZ$5,0))) -> 0 | ... BN12: =IF(BN$5="","",INDEX('Cash Flow'!$F$37:$BZ$37,1,MATCH(BN$5,'Cash Flow'!$F$5:$BZ$5,0))) -> 0
B13: Total Leasing & Capital Costs | F13: =IF(F$5="","",SUM(F11:F12)) -> 0 | G13: =IF(G$5="","",SUM(G11:G12)) -> 0 | H13: =IF(H$5="","",SUM(H11:H12)) -> 0 | I13: =IF(I$5="","",SUM(I11:I12)) -> 0 | J13: =IF(J$5="","",SUM(J11:J12)) -> 0 | K13: =IF(K$5="","",SUM(K11:K12)) -> 0 | L13: =IF(L$5="","",SUM(L11:L12)) -> 0 | M13: =IF(M$5="","",SUM(M11:M12)) -> 0 | ... BN13: =IF(BN$5="","",SUM(BN11:BN12)) -> 0
B15: REVENUE
B16: Rental Revenue
B17: Potential Base Rent | F17: =IF(F$5="","",INDEX('Cash Flow'!$F$11:$BZ$11,1,MATCH(F$5,'Cash Flow'!$F$5:$BZ$5,0))) -> 0 | G17: ='2021 T12'!D18 -> 72601.66 | H17: ='2021 T12'!E18 -> 137332.62 | I17: ='2021 T12'!F18 -> 140150.41 | J17: ='2021 T12'!G18 -> 142734.21 | K17: ='2021 T12'!H18 -> 142734.21 | L17: ='2021 T12'!I18 -> 143822.45 | M17: ='2021 T12'!J18 -> 146373.79 | N17: ='2021 T12'!K18 -> 155702.13 | ... P17: ='2021 T12'!M18 -> 160210.45 | Q17: =IF(Q$5="","",INDEX('Cash Flow'!$F$11:$BZ$11,1,MATCH(Q$5,'Cash Flow'!$F$5:$BZ$5,0))) -> 231413.54 | R17: =IF(R$5="","",INDEX('Cash Flow'!$F$11:$BZ$11,1,MATCH(R$5,'Cash Flow'!$F$5:$BZ$5,0))) -> 230176.04 | S17: =IF(S$5="","",INDEX('Cash Flow'!$F$11:$BZ$11,1,MATCH(S$5,'Cash Flow'!$F$5:$BZ$5,0))) -> 232454.24 | T17: =IF(T$5="","",INDEX('Cash Flow'!$F$11:$BZ$11,1,MATCH(T$5,'Cash Flow'!$F$5:$BZ$5,0))) -> 232454.24 | U17: =IF(U$5="","",INDEX('Cash Flow'!$F$11:$BZ$11,1,MATCH(U$5,'Cash Flow'!$F$5:$BZ$5,0))) -> 232193.34 | V17: =IF(V$5="","",INDEX('Cash Flow'!$F$11:$BZ$11,1,MATCH(V$5,'Cash Flow'!$F$5:$BZ$5,0))) -> 232917.48 | W17: =IF(W$5="","",INDEX('Cash Flow'!$F$11:$BZ$11,1,MATCH(W$5,'Cash Flow'!$F$5:$BZ$5,0))) -> 233184.83 | X17: =IF(X$5="","",INDEX('Cash Flow'!$F$11:$BZ$11,1,MATCH(X$5,'Cash Flow'!$F$5:$BZ$5,0))) -> 234057.78 | ... BN17: =IF(BN$5="","",INDEX('Cash Flow'!$F$11:$BZ$11,1,MATCH(BN$5,'Cash Flow'!$F$5:$BZ$5,0))) -> 250952
B18: Absorption & Turnover Vacancy | F18: =IF(F$5="","",INDEX('Cash Flow'!$F$12:$BZ$12,1,MATCH(F$5,'Cash Flow'!$F$5:$BZ$5,0))) -> 0 | Q18: =IF(Q$5="","",INDEX('Cash Flow'!$F$12:$BZ$12,1,MATCH(Q$5,'Cash Flow'!$F$5:$BZ$5,0))) -> -88476.5 | R18: =IF(R$5="","",INDEX('Cash Flow'!$F$12:$BZ$12,1,MATCH(R$5,'Cash Flow'!$F$5:$BZ$5,0))) -> -72114 | S18: =IF(S$5="","",INDEX('Cash Flow'!$F$12:$BZ$12,1,MATCH(S$5,'Cash Flow'!$F$5:$BZ$5,0))) -> -73934.7 | T18: =IF(T$5="","",INDEX('Cash Flow'!$F$12:$BZ$12,1,MATCH(T$5,'Cash Flow'!$F$5:$BZ$5,0))) -> -73934.7 | U18: =IF(U$5="","",INDEX('Cash Flow'!$F$12:$BZ$12,1,MATCH(U$5,'Cash Flow'!$F$5:$BZ$5,0))) -> -77504.7 | V18: =IF(V$5="","",INDEX('Cash Flow'!$F$12:$BZ$12,1,MATCH(V$5,'Cash Flow'!$F$5:$BZ$5,0))) -> -77504.7 | W18: =IF(W$5="","",INDEX('Cash Flow'!$F$12:$BZ$12,1,MATCH(W$5,'Cash Flow'!$F$5:$BZ$5,0))) -> -77504.7 | X18: =IF(X$5="","",INDEX('Cash Flow'!$F$12:$BZ$12,1,MATCH(X$5,'Cash Flow'!$F$5:$BZ$5,0))) -> -66080.7 | ... BN18: =IF(BN$5="","",INDEX('Cash Flow'!$F$12:$BZ$12,1,MATCH(BN$5,'Cash Flow'!$F$5:$BZ$5,0))) -> 0
B19: Free Rent | F19: =IF(F$5="","",INDEX('Cash Flow'!$F$13:$BZ$13,1,MATCH(F$5,'Cash Flow'!$F$5:$BZ$5,0))) -> 0 | G19: =IF(G$5="","",INDEX('Cash Flow'!$F$13:$BZ$13,1,MATCH(G$5,'Cash Flow'!$F$5:$BZ$5,0))) -> 0 | H19: =IF(H$5="","",INDEX('Cash Flow'!$F$13:$BZ$13,1,MATCH(H$5,'Cash Flow'!$F$5:$BZ$5,0))) -> 0 | I19: =IF(I$5="","",INDEX('Cash Flow'!$F$13:$BZ$13,1,MATCH(I$5,'Cash Flow'!$F$5:$BZ$5,0))) -> 0 | J19: =IF(J$5="","",INDEX('Cash Flow'!$F$13:$BZ$13,1,MATCH(J$5,'Cash Flow'!$F$5:$BZ$5,0))) -> 0 | K19: =IF(K$5="","",INDEX('Cash Flow'!$F$13:$BZ$13,1,MATCH(K$5,'Cash Flow'!$F$5:$BZ$5,0))) -> 0 | L19: =IF(L$5="","",INDEX('Cash Flow'!$F$13:$BZ$13,1,MATCH(L$5,'Cash Flow'!$F$5:$BZ$5,0))) -> 0 | M19: =IF(M$5="","",INDEX('Cash Flow'!$F$13:$BZ$13,1,MATCH(M$5,'Cash Flow'!$F$5:$BZ$5,0))) -> 0 | ... BN19: =IF(BN$5="","",INDEX('Cash Flow'!$F$13:$BZ$13,1,MATCH(BN$5,'Cash Flow'!$F$5:$BZ$5,0))) -> 0
B20: Scheduled Base Rent | F20: =IF(F$5="","",INDEX('Cash Flow'!$F$14:$BZ$14,1,MATCH(F$5,'Cash Flow'!$F$5:$BZ$5,0))) -> 0 | G20: =SUM(G17:G19) -> 72601.66 | H20: =SUM(H17:H19) -> 137332.62 | I20: =SUM(I17:I19) -> 140150.41 | J20: =SUM(J17:J19) -> 142734.21 | K20: =SUM(K17:K19) -> 142734.21 | L20: =SUM(L17:L19) -> 143822.45 | M20: =SUM(M17:M19) -> 146373.79 | N20: =SUM(N17:N19) -> 155702.13 | ... BN20: =SUM(BN17:BN19) -> 250952
B21: Tenant Recovery | F21: =IF(F$5="","",INDEX('Cash Flow'!$F$15:$BZ$15,1,MATCH(F$5,'Cash Flow'!$F$5:$BZ$5,0))) -> 0 | G21: ='2021 T12'!D33 -> 46104.88 | H21: ='2021 T12'!E33 -> 78970.98 | I21: ='2021 T12'!F33 -> 78971 | J21: ='2021 T12'!G33 -> 78971 | K21: ='2021 T12'!H33 -> 41861.01 | L21: ='2021 T12'!I33 -> 78971 | M21: ='2021 T12'!J33 -> 72237.62 | N21: ='2021 T12'!K33 -> 87232.46 | ... P21: ='2021 T12'!M33 -> 90041.48 | Q21: =IF(Q$5="","",INDEX('Cash Flow'!$F$15:$BZ$15,1,MATCH(Q$5,'Cash Flow'!$F$5:$BZ$5,0))) -> 97140.648 | R21: =IF(R$5="","",INDEX('Cash Flow'!$F$15:$BZ$15,1,MATCH(R$5,'Cash Flow'!$F$5:$BZ$5,0))) -> 97140.648 | S21: =IF(S$5="","",INDEX('Cash Flow'!$F$15:$BZ$15,1,MATCH(S$5,'Cash Flow'!$F$5:$BZ$5,0))) -> 100054.87 | T21: =IF(T$5="","",INDEX('Cash Flow'!$F$15:$BZ$15,1,MATCH(T$5,'Cash Flow'!$F$5:$BZ$5,0))) -> 100054.87 | U21: =IF(U$5="","",INDEX('Cash Flow'!$F$15:$BZ$15,1,MATCH(U$5,'Cash Flow'!$F$5:$BZ$5,0))) -> 100054.87 | V21: =IF(V$5="","",INDEX('Cash Flow'!$F$15:$BZ$15,1,MATCH(V$5,'Cash Flow'!$F$5:$BZ$5,0))) -> 100054.87 | W21: =IF(W$5="","",INDEX('Cash Flow'!$F$15:$BZ$15,1,MATCH(W$5,'Cash Flow'!$F$5:$BZ$5,0))) -> 100054.87 | X21: =IF(X$5="","",INDEX('Cash Flow'!$F$15:$BZ$15,1,MATCH(X$5,'Cash Flow'!$F$5:$BZ$5,0))) -> 100054.87 | ... BN21: =IF(BN$5="","",INDEX('Cash Flow'!$F$15:$BZ$15,1,MATCH(BN$5,'Cash Flow'!$F$5:$BZ$5,0))) -> 109332.65
B22: Parking | G22: ='2021 T12'!D39 -> 9297.67 | H22: ='2021 T12'!E39 -> 11345.35 | I22: ='2021 T12'!F39 -> 69 | J22: ='2021 T12'!G39 -> 32097.3 | K22: ='2021 T12'!H39 -> 26002.2 | L22: ='2021 T12'!I39 -> 20770.5 | M22: ='2021 T12'!J39 -> 16903.05 | N22: ='2021 T12'!K39 -> 16903.05 | ... P22: ='2021 T12'!M39 -> -11660.46 | Q22: 16000 | R22: =Q22 -> 16000 | S22: =R22 -> 16000 | T22: =S22 -> 16000 | U22: =T22 -> 16000 | V22: =U22 -> 16000 | W22: =V22 -> 16000 | X22: =W22 -> 16000 | Y22: =X22 -> 16000 | ... AB22: =AA22 -> 16000 | AC22: =AB22*1.03 -> 16480 | AD22: =AC22 -> 16480 | AE22: =AD22 -> 16480 | AF22: =AE22 -> 16480 | AG22: =AF22 -> 16480 | AH22: =AG22 -> 16480 | AI22: =AH22 -> 16480 | AJ22: =AI22 -> 16480 | AK22: =AJ22 -> 16480 | ... AN22: =AM22 -> 16480 | AO22: =AN22*1.03 -> 16974.4 | AP22: =AO22*1.03 -> 17483.632 | AQ22: =AP22 -> 17483.632 | AR22: =AQ22 -> 17483.632 | AS22: =AR22 -> 17483.632 | AT22: =AS22 -> 17483.632 | AU22: =AT22 -> 17483.632 | AV22: =AU22 -> 17483.632 | AW22: =AV22 -> 17483.632 | AX22: =AW22 -> 17483.632 | ... AZ22: =AY22 -> 17483.632 | BA22: =AZ22*1.03 -> 18008.141 | BB22: =BA22 -> 18008.141 | BC22: =BB22 -> 18008.141 | BD22: =BC22 -> 18008.141 | BE22: =BD22 -> 18008.141 | BF22: =BE22 -> 18008.141 | BG22: =BF22 -> 18008.141 | BH22: =BG22 -> 18008.141 | BI22: =BH22 -> 18008.141 | ... BL22: =BK22 -> 18008.141 | BM22: =BL22*1.03 -> 18548.385 | BN22: =BM22 -> 18548.385
B23: Potential Gross Revenue | F23: =IF(F$5="","",INDEX('Cash Flow'!$F$16:$BZ$16,1,MATCH(F$5,'Cash Flow'!$F$5:$BZ$5,0))) -> 0 | G23: =SUM(G20:G22) -> 128004.21 | H23: =SUM(H20:H22) -> 227648.95 | I23: =SUM(I20:I22) -> 219190.41 | J23: =SUM(J20:J22) -> 253802.51 | K23: =SUM(K20:K22) -> 210597.42 | L23: =SUM(L20:L22) -> 243563.95 | M23: =SUM(M20:M22) -> 235514.46 | N23: =SUM(N20:N22) -> 259837.64 | ... BN23: =SUM(BN20:BN22) -> 378833.04
B24: Vacancy & Credit Loss | F24: =IF(F$5="","",INDEX('Cash Flow'!$F$17:$BZ$17,1,MATCH(F$5,'Cash Flow'!$F$5:$BZ$5,0))) -> 0 | G24: =IF(G$5="","",INDEX('Cash Flow'!$F$17:$BZ$17,1,MATCH(G$5,'Cash Flow'!$F$5:$BZ$5,0))) -> 0 | H24: =IF(H$5="","",INDEX('Cash Flow'!$F$17:$BZ$17,1,MATCH(H$5,'Cash Flow'!$F$5:$BZ$5,0))) -> 0 | I24: =IF(I$5="","",INDEX('Cash Flow'!$F$17:$BZ$17,1,MATCH(I$5,'Cash Flow'!$F$5:$BZ$5,0))) -> 0 | J24: =IF(J$5="","",INDEX('Cash Flow'!$F$17:$BZ$17,1,MATCH(J$5,'Cash Flow'!$F$5:$BZ$5,0))) -> 0 | K24: =IF(K$5="","",INDEX('Cash Flow'!$F$17:$BZ$17,1,MATCH(K$5,'Cash Flow'!$F$5:$BZ$5,0))) -> 0 | L24: =IF(L$5="","",INDEX('Cash Flow'!$F$17:$BZ$17,1,MATCH(L$5,'Cash Flow'!$F$5:$BZ$5,0))) -> 0 | M24: =IF(M$5="","",INDEX('Cash Flow'!$F$17:$BZ$17,1,MATCH(M$5,'Cash Flow'!$F$5:$BZ$5,0))) -> 0 | ... BN24: =IF(BN$5="","",INDEX('Cash Flow'!$F$17:$BZ$17,1,MATCH(BN$5,'Cash Flow'!$F$5:$BZ$5,0))) -> -18014.233
B25: Effective Gross Revenue | F25: =IF(F$5="","",INDEX('Cash Flow'!$F$18:$BZ$18,1,MATCH(F$5,'Cash Flow'!$F$5:$BZ$5,0))) -> 0 | G25: =G23+G24 -> 128004.21 | H25: =H23+H24 -> 227648.95 | I25: =I23+I24 -> 219190.41 | J25: =J23+J24 -> 253802.51 | K25: =K23+K24 -> 210597.42 | L25: =L23+L24 -> 243563.95 | M25: =M23+M24 -> 235514.46 | N25: =N23+N24 -> 259837.64 | ... BN25: =BN23+BN24 -> 360818.81
B27: Occupancy: | Q27: =Q20/Q17 -> 0.6176693 | R27: =R20/R17 -> 0.68670067 | S27: =S20/S17 -> 0.68193869 | T27: =T20/T17 -> 0.68193869 | U27: =U20/U17 -> 0.66620619 | V27: =V20/V17 -> 0.66724395 | W27: =W20/W17 -> 0.66762546 | X27: =X20/X17 -> 0.71767356 | ... BN27: =BN20/BN17 -> 1
B30: OPERATING EXPENSES
B31: Repair & Maintenance Expense | F31: =IF(F$5="","",INDEX('Cash Flow'!$F$21:$BZ$21,1,MATCH(F$5,'Cash Flow'!$F$5:$BZ$5,0))) -> 0 | G31: =IF(G$5="","",INDEX('Cash Flow'!$F$21:$BZ$21,1,MATCH(G$5,'Cash Flow'!$F$5:$BZ$5,0))) -> -29234.25 | H31: =IF(H$5="","",INDEX('Cash Flow'!$F$21:$BZ$21,1,MATCH(H$5,'Cash Flow'!$F$5:$BZ$5,0))) -> -42334.55 | I31: =IF(I$5="","",INDEX('Cash Flow'!$F$21:$BZ$21,1,MATCH(I$5,'Cash Flow'!$F$5:$BZ$5,0))) -> -25405.2 | J31: =IF(J$5="","",INDEX('Cash Flow'!$F$21:$BZ$21,1,MATCH(J$5,'Cash Flow'!$F$5:$BZ$5,0))) -> -17614.61 | K31: =IF(K$5="","",INDEX('Cash Flow'!$F$21:$BZ$21,1,MATCH(K$5,'Cash Flow'!$F$5:$BZ$5,0))) -> -21129.95 | L31: =IF(L$5="","",INDEX('Cash Flow'!$F$21:$BZ$21,1,MATCH(L$5,'Cash Flow'!$F$5:$BZ$5,0))) -> -44306.55 | M31: =IF(M$5="","",INDEX('Cash Flow'!$F$21:$BZ$21,1,MATCH(M$5,'Cash Flow'!$F$5:$BZ$5,0))) -> -27865.6 | ... BN31: =IF(BN$5="","",INDEX('Cash Flow'!$F$21:$BZ$21,1,MATCH(BN$5,'Cash Flow'!$F$5:$BZ$5,0))) -> -25378.585
B32: Utilities Expense | F32: =IF(F$5="","",INDEX('Cash Flow'!$F$22:$BZ$22,1,MATCH(F$5,'Cash Flow'!$F$5:$BZ$5,0))) -> 0 | G32: =IF(G$5="","",INDEX('Cash Flow'!$F$22:$BZ$22,1,MATCH(G$5,'Cash Flow'!$F$5:$BZ$5,0))) -> -40396.37 | H32: =IF(H$5="","",INDEX('Cash Flow'!$F$22:$BZ$22,1,MATCH(H$5,'Cash Flow'!$F$5:$BZ$5,0))) -> -16313.27 | I32: =IF(I$5="","",INDEX('Cash Flow'!$F$22:$BZ$22,1,MATCH(I$5,'Cash Flow'!$F$5:$BZ$5,0))) -> -83090.98 | J32: =IF(J$5="","",INDEX('Cash Flow'!$F$22:$BZ$22,1,MATCH(J$5,'Cash Flow'!$F$5:$BZ$5,0))) -> 8019.18 | K32: =IF(K$5="","",INDEX('Cash Flow'!$F$22:$BZ$22,1,MATCH(K$5,'Cash Flow'!$F$5:$BZ$5,0))) -> -75673.95 | L32: =IF(L$5="","",INDEX('Cash Flow'!$F$22:$BZ$22,1,MATCH(L$5,'Cash Flow'!$F$5:$BZ$5,0))) -> -72184.23 | M32: =IF(M$5="","",INDEX('Cash Flow'!$F$22:$BZ$22,1,MATCH(M$5,'Cash Flow'!$F$5:$BZ$5,0))) -> -53183.94 | ... BN32: =IF(BN$5="","",INDEX('Cash Flow'!$F$22:$BZ$22,1,MATCH(BN$5,'Cash Flow'!$F$5:$BZ$5,0))) -> -42980.209
B33: Property Tax Expense | F33: =IF(F$5="","",INDEX('Cash Flow'!$F$23:$BZ$23,1,MATCH(F$5,'Cash Flow'!$F$5:$BZ$5,0))) -> 0 | G33: =IF(G$5="","",INDEX('Cash Flow'!$F$23:$BZ$23,1,MATCH(G$5,'Cash Flow'!$F$5:$BZ$5,0))) -> -39302.01 | H33: =IF(H$5="","",INDEX('Cash Flow'!$F$23:$BZ$23,1,MATCH(H$5,'Cash Flow'!$F$5:$BZ$5,0))) -> -32502.01 | I33: =IF(I$5="","",INDEX('Cash Flow'!$F$23:$BZ$23,1,MATCH(I$5,'Cash Flow'!$F$5:$BZ$5,0))) -> -32502.01 | J33: =IF(J$5="","",INDEX('Cash Flow'!$F$23:$BZ$23,1,MATCH(J$5,'Cash Flow'!$F$5:$BZ$5,0))) -> -32502 | K33: =IF(K$5="","",INDEX('Cash Flow'!$F$23:$BZ$23,1,MATCH(K$5,'Cash Flow'!$F$5:$BZ$5,0))) -> -34502.01 | L33: =IF(L$5="","",INDEX('Cash Flow'!$F$23:$BZ$23,1,MATCH(L$5,'Cash Flow'!$F$5:$BZ$5,0))) -> -32502.01 | M33: =IF(M$5="","",INDEX('Cash Flow'!$F$23:$BZ$23,1,MATCH(M$5,'Cash Flow'!$F$5:$BZ$5,0))) -> -32502.01 | ... BN33: =IF(BN$5="","",INDEX('Cash Flow'!$F$23:$BZ$23,1,MATCH(BN$5,'Cash Flow'!$F$5:$BZ$5,0))) -> -30214.322
B34: Property Insurance Expense | F34: =IF(F$5="","",INDEX('Cash Flow'!$F$24:$BZ$24,1,MATCH(F$5,'Cash Flow'!$F$5:$BZ$5,0))) -> 0 | G34: =IF(G$5="","",INDEX('Cash Flow'!$F$24:$BZ$24,1,MATCH(G$5,'Cash Flow'!$F$5:$BZ$5,0))) -> -10385.23 | H34: =IF(H$5="","",INDEX('Cash Flow'!$F$24:$BZ$24,1,MATCH(H$5,'Cash Flow'!$F$5:$BZ$5,0))) -> -10385.23 | I34: =IF(I$5="","",INDEX('Cash Flow'!$F$24:$BZ$24,1,MATCH(I$5,'Cash Flow'!$F$5:$BZ$5,0))) -> -10385.23 | J34: =IF(J$5="","",INDEX('Cash Flow'!$F$24:$BZ$24,1,MATCH(J$5,'Cash Flow'!$F$5:$BZ$5,0))) -> -10385.23 | K34: =IF(K$5="","",INDEX('Cash Flow'!$F$24:$BZ$24,1,MATCH(K$5,'Cash Flow'!$F$5:$BZ$5,0))) -> -11226.28 | L34: =IF(L$5="","",INDEX('Cash Flow'!$F$24:$BZ$24,1,MATCH(L$5,'Cash Flow'!$F$5:$BZ$5,0))) -> -11226.28 | M34: =IF(M$5="","",INDEX('Cash Flow'!$F$24:$BZ$24,1,MATCH(M$5,'Cash Flow'!$F$5:$BZ$5,0))) -> -8069.78 | ... BN34: =IF(BN$5="","",INDEX('Cash Flow'!$F$24:$BZ$24,1,MATCH(BN$5,'Cash Flow'!$F$5:$BZ$5,0))) -> -10490.68
B35: Property Management Expense | F35: =IF(F$5="","",INDEX('Cash Flow'!$F$25:$BZ$25,1,MATCH(F$5,'Cash Flow'!$F$5:$BZ$5,0))) -> 0 | G35: =IF(G$5="","",INDEX('Cash Flow'!$F$25:$BZ$25,1,MATCH(G$5,'Cash Flow'!$F$5:$BZ$5,0))) -> -8253.29 | H35: =IF(H$5="","",INDEX('Cash Flow'!$F$25:$BZ$25,1,MATCH(H$5,'Cash Flow'!$F$5:$BZ$5,0))) -> -6906.04 | I35: =IF(I$5="","",INDEX('Cash Flow'!$F$25:$BZ$25,1,MATCH(I$5,'Cash Flow'!$F$5:$BZ$5,0))) -> -5141.93 | J35: =IF(J$5="","",INDEX('Cash Flow'!$F$25:$BZ$25,1,MATCH(J$5,'Cash Flow'!$F$5:$BZ$5,0))) -> -7009.87 | K35: =IF(K$5="","",INDEX('Cash Flow'!$F$25:$BZ$25,1,MATCH(K$5,'Cash Flow'!$F$5:$BZ$5,0))) -> -5354.47 | L35: =IF(L$5="","",INDEX('Cash Flow'!$F$25:$BZ$25,1,MATCH(L$5,'Cash Flow'!$F$5:$BZ$5,0))) -> -6089.1 | M35: =IF(M$5="","",INDEX('Cash Flow'!$F$25:$BZ$25,1,MATCH(M$5,'Cash Flow'!$F$5:$BZ$5,0))) -> -5349.05 | ... BN35: =IF(BN$5="","",INDEX('Cash Flow'!$F$25:$BZ$25,1,MATCH(BN$5,'Cash Flow'!$F$5:$BZ$5,0))) -> -5666.8928
B36: Administrative Expense | F36: =IF(F$5="","",INDEX('Cash Flow'!$F$26:$BZ$26,1,MATCH(F$5,'Cash Flow'!$F$5:$BZ$5,0))) -> 0 | G36: =IF(G$5="","",INDEX('Cash Flow'!$F$26:$BZ$26,1,MATCH(G$5,'Cash Flow'!$F$5:$BZ$5,0))) -> 24103.63 | H36: =IF(H$5="","",INDEX('Cash Flow'!$F$26:$BZ$26,1,MATCH(H$5,'Cash Flow'!$F$5:$BZ$5,0))) -> -1405.85 | I36: =IF(I$5="","",INDEX('Cash Flow'!$F$26:$BZ$26,1,MATCH(I$5,'Cash Flow'!$F$5:$BZ$5,0))) -> -1282.29 | J36: =IF(J$5="","",INDEX('Cash Flow'!$F$26:$BZ$26,1,MATCH(J$5,'Cash Flow'!$F$5:$BZ$5,0))) -> -1229.19 | K36: =IF(K$5="","",INDEX('Cash Flow'!$F$26:$BZ$26,1,MATCH(K$5,'Cash Flow'!$F$5:$BZ$5,0))) -> -1620.26 | L36: =IF(L$5="","",INDEX('Cash Flow'!$F$26:$BZ$26,1,MATCH(L$5,'Cash Flow'!$F$5:$BZ$5,0))) -> -1488.35 | M36: =IF(M$5="","",INDEX('Cash Flow'!$F$26:$BZ$26,1,MATCH(M$5,'Cash Flow'!$F$5:$BZ$5,0))) -> -663.43 | ... BN36: =IF(BN$5="","",INDEX('Cash Flow'!$F$26:$BZ$26,1,MATCH(BN$5,'Cash Flow'!$F$5:$BZ$5,0))) -> -1197.4467
B37: Leasing & Marketing Expense | F37: =IF(F$5="","",INDEX('Cash Flow'!$F$27:$BZ$27,1,MATCH(F$5,'Cash Flow'!$F$5:$BZ$5,0))) -> 0 | G37: =IF(G$5="","",INDEX('Cash Flow'!$F$27:$BZ$27,1,MATCH(G$5,'Cash Flow'!$F$5:$BZ$5,0))) -> 0 | H37: =IF(H$5="","",INDEX('Cash Flow'!$F$27:$BZ$27,1,MATCH(H$5,'Cash Flow'!$F$5:$BZ$5,0))) -> -250 | I37: =IF(I$5="","",INDEX('Cash Flow'!$F$27:$BZ$27,1,MATCH(I$5,'Cash Flow'!$F$5:$BZ$5,0))) -> 0 | J37: =IF(J$5="","",INDEX('Cash Flow'!$F$27:$BZ$27,1,MATCH(J$5,'Cash Flow'!$F$5:$BZ$5,0))) -> 0 | K37: =IF(K$5="","",INDEX('Cash Flow'!$F$27:$BZ$27,1,MATCH(K$5,'Cash Flow'!$F$5:$BZ$5,0))) -> 0 | L37: =IF(L$5="","",INDEX('Cash Flow'!$F$27:$BZ$27,1,MATCH(L$5,'Cash Flow'!$F$5:$BZ$5,0))) -> 0 | M37: =IF(M$5="","",INDEX('Cash Flow'!$F$27:$BZ$27,1,MATCH(M$5,'Cash Flow'!$F$5:$BZ$5,0))) -> 0 | ... BN37: =IF(BN$5="","",INDEX('Cash Flow'!$F$27:$BZ$27,1,MATCH(BN$5,'Cash Flow'!$F$5:$BZ$5,0))) -> -22.765146
B38: Professional Service Expense | F38: =IF(F$5="","",INDEX('Cash Flow'!$F$28:$BZ$28,1,MATCH(F$5,'Cash Flow'!$F$5:$BZ$5,0))) -> 0 | G38: =IF(G$5="","",INDEX('Cash Flow'!$F$28:$BZ$28,1,MATCH(G$5,'Cash Flow'!$F$5:$BZ$5,0))) -> -2390.04 | H38: =IF(H$5="","",INDEX('Cash Flow'!$F$28:$BZ$28,1,MATCH(H$5,'Cash Flow'!$F$5:$BZ$5,0))) -> -5225 | I38: =IF(I$5="","",INDEX('Cash Flow'!$F$28:$BZ$28,1,MATCH(I$5,'Cash Flow'!$F$5:$BZ$5,0))) -> -1961 | J38: =IF(J$5="","",INDEX('Cash Flow'!$F$28:$BZ$28,1,MATCH(J$5,'Cash Flow'!$F$5:$BZ$5,0))) -> -1875 | K38: =IF(K$5="","",INDEX('Cash Flow'!$F$28:$BZ$28,1,MATCH(K$5,'Cash Flow'!$F$5:$BZ$5,0))) -> -2025 | L38: =IF(L$5="","",INDEX('Cash Flow'!$F$28:$BZ$28,1,MATCH(L$5,'Cash Flow'!$F$5:$BZ$5,0))) -> -5316.57 | M38: =IF(M$5="","",INDEX('Cash Flow'!$F$28:$BZ$28,1,MATCH(M$5,'Cash Flow'!$F$5:$BZ$5,0))) -> -3450 | ... BN38: =IF(BN$5="","",INDEX('Cash Flow'!$F$28:$BZ$28,1,MATCH(BN$5,'Cash Flow'!$F$5:$BZ$5,0))) -> -3505.8325
B39: Non-Capitalized Expenditure | F39: =IF(F$5="","",INDEX('Cash Flow'!$F$29:$BZ$29,1,MATCH(F$5,'Cash Flow'!$F$5:$BZ$5,0))) -> 0 | G39: =IF(G$5="","",INDEX('Cash Flow'!$F$29:$BZ$29,1,MATCH(G$5,'Cash Flow'!$F$5:$BZ$5,0))) -> -2926 | H39: =IF(H$5="","",INDEX('Cash Flow'!$F$29:$BZ$29,1,MATCH(H$5,'Cash Flow'!$F$5:$BZ$5,0))) -> 0 | I39: =IF(I$5="","",INDEX('Cash Flow'!$F$29:$BZ$29,1,MATCH(I$5,'Cash Flow'!$F$5:$BZ$5,0))) -> 0 | J39: =IF(J$5="","",INDEX('Cash Flow'!$F$29:$BZ$29,1,MATCH(J$5,'Cash Flow'!$F$5:$BZ$5,0))) -> -2926 | K39: =IF(K$5="","",INDEX('Cash Flow'!$F$29:$BZ$29,1,MATCH(K$5,'Cash Flow'!$F$5:$BZ$5,0))) -> 0 | L39: =IF(L$5="","",INDEX('Cash Flow'!$F$29:$BZ$29,1,MATCH(L$5,'Cash Flow'!$F$5:$BZ$5,0))) -> -1463 | M39: =IF(M$5="","",INDEX('Cash Flow'!$F$29:$BZ$29,1,MATCH(M$5,'Cash Flow'!$F$5:$BZ$5,0))) -> 0 | ... BN39: =IF(BN$5="","",INDEX('Cash Flow'!$F$29:$BZ$29,1,MATCH(BN$5,'Cash Flow'!$F$5:$BZ$5,0))) -> 0
B40: Direct Billable Expense | F40: =IF(F$5="","",INDEX('Cash Flow'!$F$30:$BZ$30,1,MATCH(F$5,'Cash Flow'!$F$5:$BZ$5,0))) -> 0 | G40: =IF(G$5="","",INDEX('Cash Flow'!$F$30:$BZ$30,1,MATCH(G$5,'Cash Flow'!$F$5:$BZ$5,0))) -> 0 | H40: =IF(H$5="","",INDEX('Cash Flow'!$F$30:$BZ$30,1,MATCH(H$5,'Cash Flow'!$F$5:$BZ$5,0))) -> 0 | I40: =IF(I$5="","",INDEX('Cash Flow'!$F$30:$BZ$30,1,MATCH(I$5,'Cash Flow'!$F$5:$BZ$5,0))) -> 0 | J40: =IF(J$5="","",INDEX('Cash Flow'!$F$30:$BZ$30,1,MATCH(J$5,'Cash Flow'!$F$5:$BZ$5,0))) -> 0 | K40: =IF(K$5="","",INDEX('Cash Flow'!$F$30:$BZ$30,1,MATCH(K$5,'Cash Flow'!$F$5:$BZ$5,0))) -> 0 | L40: =IF(L$5="","",INDEX('Cash Flow'!$F$30:$BZ$30,1,MATCH(L$5,'Cash Flow'!$F$5:$BZ$5,0))) -> -566.57 | M40: =IF(M$5="","",INDEX('Cash Flow'!$F$30:$BZ$30,1,MATCH(M$5,'Cash Flow'!$F$5:$BZ$5,0))) -> 0 | ... BN40: =IF(BN$5="","",INDEX('Cash Flow'!$F$30:$BZ$30,1,MATCH(BN$5,'Cash Flow'!$F$5:$BZ$5,0))) -> -228.65312
B41: Total Operating Expenses | F41: =SUM(F31:F40) -> 0 | G41: =SUM(G31:G40) -> -108783.56 | H41: =SUM(H31:H40) -> -115321.95 | I41: =SUM(I31:I40) -> -159768.64 | J41: =SUM(J31:J40) -> -65522.72 | K41: =SUM(K31:K40) -> -151531.92 | L41: =SUM(L31:L40) -> -175142.66 | M41: =SUM(M31:M40) -> -131083.81 | ... BN41: =SUM(BN31:BN40) -> -119685.39
B43: Net Operating Income | F43: =IF(F$5="","",INDEX('Cash Flow'!$F$33:$BZ$33,1,MATCH(F$5,'Cash Flow'!$F$5:$BZ$5,0))) -> 0 | G43: =G25+G41 -> 19220.65 | H43: =H25+H41 -> 112327 | I43: =I25+I41 -> 59421.77 | J43: =J25+J41 -> 188279.79 | K43: =K25+K41 -> 59065.5 | L43: =L25+L41 -> 68421.29 | M43: =M25+M41 -> 104430.65 | N43: =N25+N41 -> 175250.97 | ... BN43: =BN25+BN41 -> 241133.42
B45: Disposition | F45: =IF(F$5="","",IF(F$5=Assumption!$D$4,Assumption!$D$17-Assumption!$D$18,0)) -> 0 | G45: =IF(G$5="","",IF(G$5=Assumption!$D$4,Assumption!$D$17-Assumption!$D$18,0)) -> 0 | H45: =IF(H$5="","",IF(H$5=Assumption!$D$4,Assumption!$D$17-Assumption!$D$18,0)) -> 0 | I45: =IF(I$5="","",IF(I$5=Assumption!$D$4,Assumption!$D$17-Assumption!$D$18,0)) -> 0 | J45: =IF(J$5="","",IF(J$5=Assumption!$D$4,Assumption!$D$17-Assumption!$D$18,0)) -> 0 | K45: =IF(K$5="","",IF(K$5=Assumption!$D$4,Assumption!$D$17-Assumption!$D$18,0)) -> 0 | L45: =IF(L$5="","",IF(L$5=Assumption!$D$4,Assumption!$D$17-Assumption!$D$18,0)) -> 0 | M45: =IF(M$5="","",IF(M$5=Assumption!$D$4,Assumption!$D$17-Assumption!$D$18,0)) -> 0 | ... BN45: =IF(BN$5="","",IF(BN$5=Assumption!$D$4,Assumption!$D$17-Assumption!$D$18,0)) -> 43818419
B46: Unlevered Cash Flow | F46: =IF(F$5="","",SUM(F8,F13,F43,F45)) -> -25507409 | G46: =IF(G$5="","",SUM(G8,G13,G43,G45)) -> 19220.65 | H46: =IF(H$5="","",SUM(H8,H13,H43,H45)) -> 112327 | I46: =IF(I$5="","",SUM(I8,I13,I43,I45)) -> 59421.77 | J46: =IF(J$5="","",SUM(J8,J13,J43,J45)) -> 188279.79 | K46: =IF(K$5="","",SUM(K8,K13,K43,K45)) -> 59065.5 | L46: =IF(L$5="","",SUM(L8,L13,L43,L45)) -> 68421.29 | M46: =IF(M$5="","",SUM(M8,M13,M43,M45)) -> 104430.65 | ... BN46: =IF(BN$5="","",SUM(BN8,BN13,BN43,BN45)) -> 44059553
B47: Annualized Unlevered IRR | F47: =IFERROR((1+IRR(F46:BN46))^12-1,"") -> 0.14936969
B49: Debt and Equity | C49: Debt pays TI and LC by the way
B50: Equity | F50: =IF(F$5="","",-MIN(0,F61)) -> 11709551 | G50: =IF(G$5="","",-MIN(0,G61)) -> 65232.45 | H50: =IF(H$5="","",-MIN(0,H61)) -> 0 | I50: =IF(I$5="","",-MIN(0,I61)) -> 25031.33 | J50: =IF(J$5="","",-MIN(0,J61)) -> 0 | K50: =IF(K$5="","",-MIN(0,K61)) -> 25387.6 | L50: =IF(L$5="","",-MIN(0,L61)) -> 16031.81 | M50: =IF(M$5="","",-MIN(0,M61)) -> 0 | ... BN50: =IF(BN$5="","",-MIN(0,BN61)) -> 0
...

Sheet Cash Flow
C2: DCF
C4: Year | F4: 0 | G4: =IF(G5="","",ROUNDUP(G5/12,0)) -> 1 | H4: =IF(H5="","",ROUNDUP(H5/12,0)) -> 1 | I4: =IF(I5="","",ROUNDUP(I5/12,0)) -> 1 | J4: =IF(J5="","",ROUNDUP(J5/12,0)) -> 1 | K4: =IF(K5="","",ROUNDUP(K5/12,0)) -> 1 | L4: =IF(L5="","",ROUNDUP(L5/12,0)) -> 1 | M4: =IF(M5="","",ROUNDUP(M5/12,0)) -> 1 | N4: =IF(N5="","",ROUNDUP(N5/12,0)) -> 1 | ... CO4: =IF(CO5="","",ROUNDUP(CO5/12,0))
C5: Month | F5: 0 | G5: =IF(F5>=Assumption!$D$4+12,"",F5+1) -> 1 | H5: =IF(G5>=Assumption!$D$4+12,"",G5+1) -> 2 | I5: =IF(H5>=Assumption!$D$4+12,"",H5+1) -> 3 | J5: =IF(I5>=Assumption!$D$4+12,"",I5+1) -> 4 | K5: =IF(J5>=Assumption!$D$4+12,"",J5+1) -> 5 | L5: =IF(K5>=Assumption!$D$4+12,"",K5+1) -> 6 | M5: =IF(L5>=Assumption!$D$4+12,"",L5+1) -> 7 | N5: =IF(M5>=Assumption!$D$4+12,"",M5+1) -> 8 | ... CO5: =IF(CN5>=Assumption!$D$4+12,"",CN5+1)
C6: Date | F6: =Assumption!D3 -> 44256 | G6: =IF(G$5="","",EOMONTH($F$6,G$5-1)) -> 44286 | H6: =IF(H$5="","",EOMONTH($F$6,H$5-1)) -> 44316 | I6: =IF(I$5="","",EOMONTH($F$6,I$5-1)) -> 44347 | J6: =IF(J$5="","",EOMONTH($F$6,J$5-1)) -> 44377 | K6: =IF(K$5="","",EOMONTH($F$6,K$5-1)) -> 44408 | L6: =IF(L$5="","",EOMONTH($F$6,L$5-1)) -> 44439 | M6: =IF(M$5="","",EOMONTH($F$6,M$5-1)) -> 44469 | N6: =IF(N$5="","",EOMONTH($F$6,N$5-1)) -> 44500 | ... CO6: =IF(CO$5="","",EOMONTH($F$6,CO$5-1))
C8: ARGUS-Style Cash Flow
C9: REVENUE | G9: Not updated
C10: Rental Revenue
C11: Potential Base Rent | G11: {=IF(G$5="","",INDEX('Lease Roll Over'!$N$97:$CK$97,1,G$5))} -> 228981 | H11: {=IF(H$5="","",INDEX('Lease Roll Over'!$N$97:$CK$97,1,H$5))} -> 228981 | I11: {=IF(I$5="","",INDEX('Lease Roll Over'!$N$97:$CK$97,1,I$5))} -> 229161.9 | J11: {=IF(J$5="","",INDEX('Lease Roll Over'!$N$97:$CK$97,1,J$5))} -> 229864.95 | K11: {=IF(K$5="","",INDEX('Lease Roll Over'!$N$97:$CK$97,1,K$5))} -> 230124.51 | L11: {=IF(L$5="","",INDEX('Lease Roll Over'!$N$97:$CK$97,1,L$5))} -> 230972.04 | M11: {=IF(M$5="","",INDEX('Lease Roll Over'!$N$97:$CK$97,1,M$5))} -> 230972.04 | N11: {=IF(N$5="","",INDEX('Lease Roll Over'!$N$97:$CK$97,1,N$5))} -> 231338.49 | ... BZ11: {=IF(BZ$5="","",INDEX('Lease Roll Over'!$N$97:$CK$97,1,BZ$5))} -> 247797.41 | CA11: {=IF(CA$5="","",INDEX('Lease Roll Over'!$N$61:$CK$61,1,CA$5))} | CB11: {=IF(CB$5="","",INDEX('Lease Roll Over'!$N$61:$CK$61,1,CB$5))} | CC11: {=IF(CC$5="","",INDEX('Lease Roll Over'!$N$61:$CK$61,1,CC$5))} | CD11: {=IF(CD$5="","",INDEX('Lease Roll Over'!$N$61:$CK$61,1,CD$5))} | CE11: {=IF(CE$5="","",INDEX('Lease Roll Over'!$N$61:$CK$61,1,CE$5))} | CF11: {=IF(CF$5="","",INDEX('Lease Roll Over'!$N$61:$CK$61,1,CF$5))} | CG11: {=IF(CG$5="","",INDEX('Lease Roll Over'!$N$61:$CK$61,1,CG$5))} | CH11: {=IF(CH$5="","",INDEX('Lease Roll Over'!$N$61:$CK$61,1,CH$5))} | ... CO11: {=IF(CO$5="","",INDEX('Lease Roll Over'!$N$61:$CK$61,1,CO$5))}
C12: Absorption & Turnover Vacancy | G12: {=IF(G$5="","",INDEX('Lease Roll Over'!$N$62:$CK$62,1,G$5)-G11)} -> -88655 | H12: {=IF(H$5="","",INDEX('Lease Roll Over'!$N$62:$CK$62,1,H$5)-H11)} -> -88655 | I12: {=IF(I$5="","",INDEX('Lease Roll Over'!$N$62:$CK$62,1,I$5)-I11)} -> -88655 | J12: {=IF(J$5="","",INDEX('Lease Roll Over'!$N$62:$CK$62,1,J$5)-J11)} -> -88655 | K12: {=IF(K$5="","",INDEX('Lease Roll Over'!$N$62:$CK$62,1,K$5)-K11)} -> -88655 | L12: {=IF(L$5="","",INDEX('Lease Roll Over'!$N$62:$CK$62,1,L$5)-L11)} -> -88655 | M12: {=IF(M$5="","",INDEX('Lease Roll Over'!$N$62:$CK$62,1,M$5)-M11)} -> -88655 | N12: {=IF(N$5="","",INDEX('Lease Roll Over'!$N$62:$CK$62,1,N$5)-N11)} -> -88655 | ... CO12: {=IF(CO$5="","",INDEX('Lease Roll Over'!$N$62:$CK$62,1,CO$5)-CO11)}
C13: Free Rent | G13: =IF(G$5="","",0) -> 0 | H13: =IF(H$5="","",0) -> 0 | I13: =IF(I$5="","",0) -> 0 | J13: =IF(J$5="","",0) -> 0 | K13: =IF(K$5="","",0) -> 0 | L13: =IF(L$5="","",0) -> 0 | M13: =IF(M$5="","",0) -> 0 | N13: =IF(N$5="","",0) -> 0 | ... CO13: =IF(CO$5="","",0)
C14: Scheduled Base Rent | G14: =IF(G$5="","",SUM(G11:G13)) -> 140326 | H14: =IF(H$5="","",SUM(H11:H13)) -> 140326 | I14: =IF(I$5="","",SUM(I11:I13)) -> 140506.9 | J14: =IF(J$5="","",SUM(J11:J13)) -> 141209.95 | K14: =IF(K$5="","",SUM(K11:K13)) -> 141469.51 | L14: =IF(L$5="","",SUM(L11:L13)) -> 142317.04 | M14: =IF(M$5="","",SUM(M11:M13)) -> 142317.04 | N14: =IF(N$5="","",SUM(N11:N13)) -> 142683.49 | ... CO14: =IF(CO$5="","",SUM(CO11:CO13))
C15: Other Tenant Revenue | D15: =SUM('2020 T12'!D21:O21)/12 -> 97140.648 | E15: 0.03 | G15: =IF(G$5="","",$D15*(1+$E15)^(G$4-1)) -> 97140.648 | H15: =IF(H$5="","",$D15*(1+$E15)^(H$4-1)) -> 97140.648 | I15: =IF(I$5="","",$D15*(1+$E15)^(I$4-1)) -> 97140.648 | J15: =IF(J$5="","",$D15*(1+$E15)^(J$4-1)) -> 97140.648 | K15: =IF(K$5="","",$D15*(1+$E15)^(K$4-1)) -> 97140.648 | L15: =IF(L$5="","",$D15*(1+$E15)^(L$4-1)) -> 97140.648 | M15: =IF(M$5="","",$D15*(1+$E15)^(M$4-1)) -> 97140.648 | N15: =IF(N$5="","",$D15*(1+$E15)^(N$4-1)) -> 97140.648 | ... CO15: =IF(CO$5="","",$D15*(1+$E15)^(CO$4-1))
C16: Potential Gross Revenue | G16: =IF(G$5="","",SUM(G14:G15)) -> 237466.65 | H16: =IF(H$5="","",SUM(H14:H15)) -> 237466.65 | I16: =IF(I$5="","",SUM(I14:I15)) -> 237647.55 | J16: =IF(J$5="","",SUM(J14:J15)) -> 238350.6 | K16: =IF(K$5="","",SUM(K14:K15)) -> 238610.16 | L16: =IF(L$5="","",SUM(L14:L15)) -> 239457.69 | M16: =IF(M$5="","",SUM(M14:M15)) -> 239457.69 | N16: =IF(N$5="","",SUM(N14:N15)) -> 239824.14 | ... CO16: =IF(CO$5="","",SUM(CO14:CO15))
C17: Vacancy & Credit Loss | E17: 0.05 | G17: {=IF(G$5="","",IF(SUMPRODUCT(--(INDEX('Lease Roll Over'!$N$12:$CK$26,0,G$5)>0))>=COUNT('Lease Roll Over'!$B$12:$B$26),-G16*$E$17,0))} -> 0 | H17: {=IF(H$5="","",IF(SUMPRODUCT(--(INDEX('Lease Roll Over'!$N$12:$CK$26,0,H$5)>0))>=COUNT('Lease Roll Over'!$B$12:$B$26),-H16*$E$17,0))} -> 0 | I17: {=IF(I$5="","",IF(SUMPRODUCT(--(INDEX('Lease Roll Over'!$N$12:$CK$26,0,I$5)>0))>=COUNT('Lease Roll Over'!$B$12:$B$26),-I16*$E$17,0))} -> 0 | J17: {=IF(J$5="","",IF(SUMPRODUCT(--(INDEX('Lease Roll Over'!$N$12:$CK$26,0,J$5)>0))>=COUNT('Lease Roll Over'!$B$12:$B$26),-J16*$E$17,0))} -> 0 | K17: {=IF(K$5="","",IF(SUMPRODUCT(--(INDEX('Lease Roll Over'!$N$12:$CK$26,0,K$5)>0))>=COUNT('Lease Roll Over'!$B$12:$B$26),-K16*$E$17,0))} -> 0 | L17: {=IF(L$5="","",IF(SUMPRODUCT(--(INDEX('Lease Roll Over'!$N$12:$CK$26,0,L$5)>0))>=COUNT('Lease Roll Over'!$B$12:$B$26),-L16*$E$17,0))} -> 0 | M17: {=IF(M$5="","",IF(SUMPRODUCT(--(INDEX('Lease Roll Over'!$N$12:$CK$26,0,M$5)>0))>=COUNT('Lease Roll Over'!$B$12:$B$26),-M16*$E$17,0))} -> 0 | N17: {=IF(N$5="","",IF(SUMPRODUCT(--(INDEX('Lease Roll Over'!$N$12:$CK$26,0,N$5)>0))>=COUNT('Lease Roll Over'!$B$12:$B$26),-N16*$E$17,0))} -> 0 | ... CO17: {=IF(CO$5="","",IF(SUMPRODUCT(--(INDEX('Lease Roll Over'!$N$12:$CK$26,0,CO$5)>0))>=COUNT('Lease Roll Over'!$B$12:$B$26),-CO16*$E$17,0))}
C18: Effective Gross Revenue | G18: =IF(G$5="","",SUM(G16:G17)) -> 237466.65 | H18: =IF(H$5="","",SUM(H16:H17)) -> 237466.65 | I18: =IF(I$5="","",SUM(I16:I17)) -> 237647.55 | J18: =IF(J$5="","",SUM(J16:J17)) -> 238350.6 | K18: =IF(K$5="","",SUM(K16:K17)) -> 238610.16 | L18: =IF(L$5="","",SUM(L16:L17)) -> 239457.69 | M18: =IF(M$5="","",SUM(M16:M17)) -> 239457.69 | N18: =IF(N$5="","",SUM(N16:N17)) -> 239824.14 | ... CO18: =IF(CO$5="","",SUM(CO16:CO17))
C20: OPERATING EXPENSES | G20: Actual | H20: Actual | I20: Actual | J20: Actual | K20: Actual | L20: Actual | M20: Actual | N20: Actual | O20: Actual | P20: Actual
C21: Repair & Maintenance Expense | G21: =-'2021 T12'!D74 -> -29234.25 | H21: =-'2021 T12'!E74 -> -42334.55 | I21: =-'2021 T12'!F74 -> -25405.2 | J21: =-'2021 T12'!G74 -> -17614.61 | K21: =-'2021 T12'!H74 -> -21129.95 | L21: =-'2021 T12'!I74 -> -44306.55 | M21: =-'2021 T12'!J74 -> -27865.6 | N21: =-'2021 T12'!K74 -> -9160 | ... P21: =-'2021 T12'!M74 -> -9794.3 | Q21: {=IF(Q$5="","",-INDEX(OPEX!$F$23:$BM$23,1,Q$5))} -> -23225 | R21: {=IF(R$5="","",-INDEX(OPEX!$F$23:$BM$23,1,R$5))} -> -23225 | S21: {=IF(S$5="","",-INDEX(OPEX!$F$23:$BM$23,1,S$5))} -> -23225 | T21: {=IF(T$5="","",-INDEX(OPEX!$F$23:$BM$23,1,T$5))} -> -23225 | U21: {=IF(U$5="","",-INDEX(OPEX!$F$23:$BM$23,1,U$5))} -> -23225 | V21: {=IF(V$5="","",-INDEX(OPEX!$F$23:$BM$23,1,V$5))} -> -23225 | W21: {=IF(W$5="","",-INDEX(OPEX!$F$23:$BM$23,1,W$5))} -> -23225 | X21: {=IF(X$5="","",-INDEX(OPEX!$F$23:$BM$23,1,X$5))} -> -23225 | ... BN21: {=IF(BN$5="","",-INDEX(OPEX!$F$23:$BM$23,1,BN$5))} -> -25378.585 | BO21: {=IF(BO$5="","",-INDEX(OPEX!$F$23:$BY$23,1,BO$5))} -> -26139.942 | BP21: {=IF(BP$5="","",-INDEX(OPEX!$F$23:$BY$23,1,BP$5))} -> -26139.942 | BQ21: {=IF(BQ$5="","",-INDEX(OPEX!$F$23:$BY$23,1,BQ$5))} -> -26139.942 | BR21: {=IF(BR$5="","",-INDEX(OPEX!$F$23:$BY$23,1,BR$5))} -> -26139.942 | BS21: {=IF(BS$5="","",-INDEX(OPEX!$F$23:$BY$23,1,BS$5))} -> -26139.942 | BT21: {=IF(BT$5="","",-INDEX(OPEX!$F$23:$BY$23,1,BT$5))} -> -26139.942 | BU21: {=IF(BU$5="","",-INDEX(OPEX!$F$23:$BY$23,1,BU$5))} -> -26139.942 | BV21: {=IF(BV$5="","",-INDEX(OPEX!$F$23:$BY$23,1,BV$5))} -> -26139.942 | ... BZ21: {=IF(BZ$5="","",-INDEX(OPEX!$F$23:$BY$23,1,BZ$5))} -> -26139.942
C22: Utilities Expense | G22: =-'2021 T12'!D84 -> -40396.37 | H22: =-'2021 T12'!E84 -> -16313.27 | I22: =-'2021 T12'!F84 -> -83090.98 | J22: =-'2021 T12'!G84 -> 8019.18 | K22: =-'2021 T12'!H84 -> -75673.95 | L22: =-'2021 T12'!I84 -> -72184.23 | M22: =-'2021 T12'!J84 -> -53183.94 | N22: =-'2021 T12'!K84 -> -25909.1 | ... P22: =-'2021 T12'!M84 -> -47304.92 | Q22: {=IF(Q$5="","",-INDEX(OPEX!$F$24:$BM$24,1,Q$5))} -> -39332.98 | R22: {=IF(R$5="","",-INDEX(OPEX!$F$24:$BM$24,1,R$5))} -> -39332.98 | S22: {=IF(S$5="","",-INDEX(OPEX!$F$24:$BM$24,1,S$5))} -> -39332.98 | T22: {=IF(T$5="","",-INDEX(OPEX!$F$24:$BM$24,1,T$5))} -> -39332.98 | U22: {=IF(U$5="","",-INDEX(OPEX!$F$24:$BM$24,1,U$5))} -> -39332.98 | V22: {=IF(V$5="","",-INDEX(OPEX!$F$24:$BM$24,1,V$5))} -> -39332.98 | W22: {=IF(W$5="","",-INDEX(OPEX!$F$24:$BM$24,1,W$5))} -> -39332.98 | X22: {=IF(X$5="","",-INDEX(OPEX!$F$24:$BM$24,1,X$5))} -> -39332.98 | ... BN22: {=IF(BN$5="","",-INDEX(OPEX!$F$24:$BM$24,1,BN$5))} -> -42980.209 | BO22: {=IF(BO$5="","",-INDEX(OPEX!$F$24:$BY$24,1,BO$5))} -> -44269.615 | BP22: {=IF(BP$5="","",-INDEX(OPEX!$F$24:$BY$24,1,BP$5))} -> -44269.615 | BQ22: {=IF(BQ$5="","",-INDEX(OPEX!$F$24:$BY$24,1,BQ$5))} -> -44269.615 | BR22: {=IF(BR$5="","",-INDEX(OPEX!$F$24:$BY$24,1,BR$5))} -> -44269.615 | BS22: {=IF(BS$5="","",-INDEX(OPEX!$F$24:$BY$24,1,BS$5))} -> -44269.615 | BT22: {=IF(BT$5="","",-INDEX(OPEX!$F$24:$BY$24,1,BT$5))} -> -44269.615 | BU22: {=IF(BU$5="","",-INDEX(OPEX!$F$24:$BY$24,1,BU$5))} -> -44269.615 | BV22: {=IF(BV$5="","",-INDEX(OPEX!$F$24:$BY$24,1,BV$5))} -> -44269.615 | ... BZ22: {=IF(BZ$5="","",-INDEX(OPEX!$F$24:$BY$24,1,BZ$5))} -> -44269.615
C23: Property Tax Expense | G23: =-'2021 T12'!D94 -> -39302.01 | H23: =-'2021 T12'!E94 -> -32502.01 | I23: =-'2021 T12'!F94 -> -32502.01 | J23: =-'2021 T12'!G94 -> -32502 | K23: =-'2021 T12'!H94 -> -34502.01 | L23: =-'2021 T12'!I94 -> -32502.01 | M23: =-'2021 T12'!J94 -> -32502.01 | N23: =-'2021 T12'!K94 -> -31158.38 | ... P23: =-'2021 T12'!M94 -> -32166.08 | Q23: {=IF(Q$5="","",-INDEX(OPEX!$F$25:$BM$25,1,Q$5))} -> -27650.385 | R23: {=IF(R$5="","",-INDEX(OPEX!$F$25:$BM$25,1,R$5))} -> -27650.385 | S23: {=IF(S$5="","",-INDEX(OPEX!$F$25:$BM$25,1,S$5))} -> -27650.385 | T23: {=IF(T$5="","",-INDEX(OPEX!$F$25:$BM$25,1,T$5))} -> -27650.385 | U23: {=IF(U$5="","",-INDEX(OPEX!$F$25:$BM$25,1,U$5))} -> -27650.385 | V23: {=IF(V$5="","",-INDEX(OPEX!$F$25:$BM$25,1,V$5))} -> -27650.385 | W23: {=IF(W$5="","",-INDEX(OPEX!$F$25:$BM$25,1,W$5))} -> -27650.385 | X23: {=IF(X$5="","",-INDEX(OPEX!$F$25:$BM$25,1,X$5))} -> -27650.385 | ... BN23: {=IF(BN$5="","",-INDEX(OPEX!$F$25:$BM$25,1,BN$5))} -> -30214.322 | BO23: {=IF(BO$5="","",-INDEX(OPEX!$F$25:$BY$25,1,BO$5))} -> -31120.752 | BP23: {=IF(BP$5="","",-INDEX(OPEX!$F$25:$BY$25,1,BP$5))} -> -31120.752 | BQ23: {=IF(BQ$5="","",-INDEX(OPEX!$F$25:$BY$25,1,BQ$5))} -> -31120.752 | BR23: {=IF(BR$5="","",-INDEX(OPEX!$F$25:$BY$25,1,BR$5))} -> -31120.752 | BS23: {=IF(BS$5="","",-INDEX(OPEX!$F$25:$BY$25,1,BS$5))} -> -31120.752 | BT23: {=IF(BT$5="","",-INDEX(OPEX!$F$25:$BY$25,1,BT$5))} -> -31120.752 | BU23: {=IF(BU$5="","",-INDEX(OPEX!$F$25:$BY$25,1,BU$5))} -> -31120.752 | BV23: {=IF(BV$5="","",-INDEX(OPEX!$F$25:$BY$25,1,BV$5))} -> -31120.752 | ... BZ23: {=IF(BZ$5="","",-INDEX(OPEX!$F$25:$BY$25,1,BZ$5))} -> -31120.752
C24: Property Insurance Expense | G24: =-'2021 T12'!D101 -> -10385.23 | H24: =-'2021 T12'!E101 -> -10385.23 | I24: =-'2021 T12'!F101 -> -10385.23 | J24: =-'2021 T12'!G101 -> -10385.23 | K24: =-'2021 T12'!H101 -> -11226.28 | L24: =-'2021 T12'!I101 -> -11226.28 | M24: =-'2021 T12'!J101 -> -8069.78 | N24: =-'2021 T12'!K101 -> -8069.78 | ... P24: =-'2021 T12'!M101 -> -7420.73 | Q24: {=IF(Q$5="","",-INDEX(OPEX!$F$26:$BM$26,1,Q$5))} -> -9600.4583 | R24: {=IF(R$5="","",-INDEX(OPEX!$F$26:$BM$26,1,R$5))} -> -9600.4583 | S24: {=IF(S$5="","",-INDEX(OPEX!$F$26:$BM$26,1,S$5))} -> -9600.4583 | T24: {=IF(T$5="","",-INDEX(OPEX!$F$26:$BM$26,1,T$5))} -> -9600.4583 | U24: {=IF(U$5="","",-INDEX(OPEX!$F$26:$BM$26,1,U$5))} -> -9600.4583 | V24: {=IF(V$5="","",-INDEX(OPEX!$F$26:$BM$26,1,V$5))} -> -9600.4583 | W24: {=IF(W$5="","",-INDEX(OPEX!$F$26:$BM$26,1,W$5))} -> -9600.4583 | X24: {=IF(X$5="","",-INDEX(OPEX!$F$26:$BM$26,1,X$5))} -> -9600.4583 | ... BN24: {=IF(BN$5="","",-INDEX(OPEX!$F$26:$BM$26,1,BN$5))} -> -10490.68 | BO24: {=IF(BO$5="","",-INDEX(OPEX!$F$26:$BY$26,1,BO$5))} -> -10805.4 | BP24: {=IF(BP$5="","",-INDEX(OPEX!$F$26:$BY$26,1,BP$5))} -> -10805.4 | BQ24: {=IF(BQ$5="","",-INDEX(OPEX!$F$26:$BY$26,1,BQ$5))} -> -10805.4 | BR24: {=IF(BR$5="","",-INDEX(OPEX!$F$26:$BY$26,1,BR$5))} -> -10805.4 | BS24: {=IF(BS$5="","",-INDEX(OPEX!$F$26:$BY$26,1,BS$5))} -> -10805.4 | BT24: {=IF(BT$5="","",-INDEX(OPEX!$F$26:$BY$26,1,BT$5))} -> -10805.4 | BU24: {=IF(BU$5="","",-INDEX(OPEX!$F$26:$BY$26,1,BU$5))} -> -10805.4 | BV24: {=IF(BV$5="","",-INDEX(OPEX!$F$26:$BY$26,1,BV$5))} -> -10805.4 | ... BZ24: {=IF(BZ$5="","",-INDEX(OPEX!$F$26:$BY$26,1,BZ$5))} -> -10805.4
C25: Property Management Expense | G25: =-'2021 T12'!D106 -> -8253.29 | H25: =-'2021 T12'!E106 -> -6906.04 | I25: =-'2021 T12'!F106 -> -5141.93 | J25: =-'2021 T12'!G106 -> -7009.87 | K25: =-'2021 T12'!H106 -> -5354.47 | L25: =-'2021 T12'!I106 -> -6089.1 | M25: =-'2021 T12'!J106 -> -5349.05 | N25: =-'2021 T12'!K106 -> -5420.85 | ... P25: =-'2021 T12'!M106 -> -5484.89 | Q25: {=IF(Q$5="","",-INDEX(OPEX!$F$27:$BM$27,1,Q$5))} -> -5186.0097 | R25: {=IF(R$5="","",-INDEX(OPEX!$F$27:$BM$27,1,R$5))} -> -5186.0097 | S25: {=IF(S$5="","",-INDEX(OPEX!$F$27:$BM$27,1,S$5))} -> -5186.0097 | T25: {=IF(T$5="","",-INDEX(OPEX!$F$27:$BM$27,1,T$5))} -> -5186.0097 | U25: {=IF(U$5="","",-INDEX(OPEX!$F$27:$BM$27,1,U$5))} -> -5186.0097 | V25: {=IF(V$5="","",-INDEX(OPEX!$F$27:$BM$27,1,V$5))} -> -5186.0097 | W25: {=IF(W$5="","",-INDEX(OPEX!$F$27:$BM$27,1,W$5))} -> -5186.0097 | X25: {=IF(X$5="","",-INDEX(OPEX!$F$27:$BM$27,1,X$5))} -> -5186.0097 | ... BN25: {=IF(BN$5="","",-INDEX(OPEX!$F$27:$BM$27,1,BN$5))} -> -5666.8928 | BO25: {=IF(BO$5="","",-INDEX(OPEX!$F$27:$BY$27,1,BO$5))} -> -5836.8996 | BP25: {=IF(BP$5="","",-INDEX(OPEX!$F$27:$BY$27,1,BP$5))} -> -5836.8996 | BQ25: {=IF(BQ$5="","",-INDEX(OPEX!$F$27:$BY$27,1,BQ$5))} -> -5836.8996 | BR25: {=IF(BR$5="","",-INDEX(OPEX!$F$27:$BY$27,1,BR$5))} -> -5836.8996 | BS25: {=IF(BS$5="","",-INDEX(OPEX!$F$27:$BY$27,1,BS$5))} -> -5836.8996 | BT25: {=IF(BT$5="","",-INDEX(OPEX!$F$27:$BY$27,1,BT$5))} -> -5836.8996 | BU25: {=IF(BU$5="","",-INDEX(OPEX!$F$27:$BY$27,1,BU$5))} -> -5836.8996 | BV25: {=IF(BV$5="","",-INDEX(OPEX!$F$27:$BY$27,1,BV$5))} -> -5836.8996 | ... BZ25: {=IF(BZ$5="","",-INDEX(OPEX!$F$27:$BY$27,1,BZ$5))} -> -5836.8996
C26: Administrative Expense | G26: =-'2021 T12'!D117 -> 24103.63 | H26: =-'2021 T12'!E117 -> -1405.85 | I26: =-'2021 T12'!F117 -> -1282.29 | J26: =-'2021 T12'!G117 -> -1229.19 | K26: =-'2021 T12'!H117 -> -1620.26 | L26: =-'2021 T12'!I117 -> -1488.35 | M26: =-'2021 T12'!J117 -> -663.43 | N26: =-'2021 T12'!K117 -> -2068.56 | ... P26: =-'2021 T12'!M117 -> -1167.23 | Q26: {=IF(Q$5="","",-INDEX(OPEX!$F$28:$BM$28,1,Q$5))} -> -1095.8333 | R26: {=IF(R$5="","",-INDEX(OPEX!$F$28:$BM$28,1,R$5))} -> -1095.8333 | S26: {=IF(S$5="","",-INDEX(OPEX!$F$28:$BM$28,1,S$5))} -> -1095.8333 | T26: {=IF(T$5="","",-INDEX(OPEX!$F$28:$BM$28,1,T$5))} -> -1095.8333 | U26: {=IF(U$5="","",-INDEX(OPEX!$F$28:$BM$28,1,U$5))} -> -1095.8333 | V26: {=IF(V$5="","",-INDEX(OPEX!$F$28:$BM$28,1,V$5))} -> -1095.8333 | W26: {=IF(W$5="","",-INDEX(OPEX!$F$28:$BM$28,1,W$5))} -> -1095.8333 | X26: {=IF(X$5="","",-INDEX(OPEX!$F$28:$BM$28,1,X$5))} -> -1095.8333 | ... BN26: {=IF(BN$5="","",-INDEX(OPEX!$F$28:$BM$28,1,BN$5))} -> -1197.4467 | BO26: {=IF(BO$5="","",-INDEX(OPEX!$F$28:$BY$28,1,BO$5))} -> -1233.3701 | BP26: {=IF(BP$5="","",-INDEX(OPEX!$F$28:$BY$28,1,BP$5))} -> -1233.3701 | BQ26: {=IF(BQ$5="","",-INDEX(OPEX!$F$28:$BY$28,1,BQ$5))} -> -1233.3701 | BR26: {=IF(BR$5="","",-INDEX(OPEX!$F$28:$BY$28,1,BR$5))} -> -1233.3701 | BS26: {=IF(BS$5="","",-INDEX(OPEX!$F$28:$BY$28,1,BS$5))} -> -1233.3701 | BT26: {=IF(BT$5="","",-INDEX(OPEX!$F$28:$BY$28,1,BT$5))} -> -1233.3701 | BU26: {=IF(BU$5="","",-INDEX(OPEX!$F$28:$BY$28,1,BU$5))} -> -1233.3701 | BV26: {=IF(BV$5="","",-INDEX(OPEX!$F$28:$BY$28,1,BV$5))} -> -1233.3701 | ... BZ26: {=IF(BZ$5="","",-INDEX(OPEX!$F$28:$BY$28,1,BZ$5))} -> -1233.3701
C27: Leasing & Marketing Expense | G27: =-'2021 T12'!D123 -> 0 | H27: =-'2021 T12'!E123 -> -250 | I27: =-'2021 T12'!F123 -> 0 | J27: =-'2021 T12'!G123 -> 0 | K27: =-'2021 T12'!H123 -> 0 | L27: =-'2021 T12'!I123 -> 0 | M27: =-'2021 T12'!J123 -> 0 | N27: =-'2021 T12'!K123 -> 0 | ... P27: =-'2021 T12'!M123 -> 0 | Q27: {=IF(Q$5="","",-INDEX(OPEX!$F$29:$BM$29,1,Q$5))} -> -20.833333 | R27: {=IF(R$5="","",-INDEX(OPEX!$F$29:$BM$29,1,R$5))} -> -20.833333 | S27: {=IF(S$5="","",-INDEX(OPEX!$F$29:$BM$29,1,S$5))} -> -20.833333 | T27: {=IF(T$5="","",-INDEX(OPEX!$F$29:$BM$29,1,T$5))} -> -20.833333 | U27: {=IF(U$5="","",-INDEX(OPEX!$F$29:$BM$29,1,U$5))} -> -20.833333 | V27: {=IF(V$5="","",-INDEX(OPEX!$F$29:$BM$29,1,V$5))} -> -20.833333 | W27: {=IF(W$5="","",-INDEX(OPEX!$F$29:$BM$29,1,W$5))} -> -20.833333 | X27: {=IF(X$5="","",-INDEX(OPEX!$F$29:$BM$29,1,X$5))} -> -20.833333 | ... BN27: {=IF(BN$5="","",-INDEX(OPEX!$F$29:$BM$29,1,BN$5))} -> -22.765146 | BO27: {=IF(BO$5="","",-INDEX(OPEX!$F$29:$BY$29,1,BO$5))} -> -23.4481 | BP27: {=IF(BP$5="","",-INDEX(OPEX!$F$29:$BY$29,1,BP$5))} -> -23.4481 | BQ27: {=IF(BQ$5="","",-INDEX(OPEX!$F$29:$BY$29,1,BQ$5))} -> -23.4481 | BR27: {=IF(BR$5="","",-INDEX(OPEX!$F$29:$BY$29,1,BR$5))} -> -23.4481 | BS27: {=IF(BS$5="","",-INDEX(OPEX!$F$29:$BY$29,1,BS$5))} -> -23.4481 | BT27: {=IF(BT$5="","",-INDEX(OPEX!$F$29:$BY$29,1,BT$5))} -> -23.4481 | BU27: {=IF(BU$5="","",-INDEX(OPEX!$F$29:$BY$29,1,BU$5))} -> -23.4481 | BV27: {=IF(BV$5="","",-INDEX(OPEX!$F$29:$BY$29,1,BV$5))} -> -23.4481 | ... BZ27: {=IF(BZ$5="","",-INDEX(OPEX!$F$29:$BY$29,1,BZ$5))} -> -23.4481
C28: Professional Service Expense | G28: =-'2021 T12'!D134 -> -2390.04 | H28: =-'2021 T12'!E134 -> -5225 | I28: =-'2021 T12'!F134 -> -1961 | J28: =-'2021 T12'!G134 -> -1875 | K28: =-'2021 T12'!H134 -> -2025 | L28: =-'2021 T12'!I134 -> -5316.57 | M28: =-'2021 T12'!J134 -> -3450 | N28: =-'2021 T12'!K134 -> -2800 | ... P28: =-'2021 T12'!M134 -> -7512 | Q28: {=IF(Q$5="","",-INDEX(OPEX!$F$30:$BM$30,1,Q$5))} -> -3208.3333 | R28: {=IF(R$5="","",-INDEX(OPEX!$F$30:$BM$30,1,R$5))} -> -3208.3333 | S28: {=IF(S$5="","",-INDEX(OPEX!$F$30:$BM$30,1,S$5))} -> -3208.3333 | T28: {=IF(T$5="","",-INDEX(OPEX!$F$30:$BM$30,1,T$5))} -> -3208.3333 | U28: {=IF(U$5="","",-INDEX(OPEX!$F$30:$BM$30,1,U$5))} -> -3208.3333 | V28: {=IF(V$5="","",-INDEX(OPEX!$F$30:$BM$30,1,V$5))} -> -3208.3333 | W28: {=IF(W$5="","",-INDEX(OPEX!$F$30:$BM$30,1,W$5))} -> -3208.3333 | X28: {=IF(X$5="","",-INDEX(OPEX!$F$30:$BM$30,1,X$5))} -> -3208.3333 | ... BN28: {=IF(BN$5="","",-INDEX(OPEX!$F$30:$BM$30,1,BN$5))} -> -3505.8325 | BO28: {=IF(BO$5="","",-INDEX(OPEX!$F$30:$BY$30,1,BO$5))} -> -3611.0074 | BP28: {=IF(BP$5="","",-INDEX(OPEX!$F$30:$BY$30,1,BP$5))} -> -3611.0074 | BQ28: {=IF(BQ$5="","",-INDEX(OPEX!$F$30:$BY$30,1,BQ$5))} -> -3611.0074 | BR28: {=IF(BR$5="","",-INDEX(OPEX!$F$30:$BY$30,1,BR$5))} -> -3611.0074 | BS28: {=IF(BS$5="","",-INDEX(OPEX!$F$30:$BY$30,1,BS$5))} -> -3611.0074 | BT28: {=IF(BT$5="","",-INDEX(OPEX!$F$30:$BY$30,1,BT$5))} -> -3611.0074 | BU28: {=IF(BU$5="","",-INDEX(OPEX!$F$30:$BY$30,1,BU$5))} -> -3611.0074 | BV28: {=IF(BV$5="","",-INDEX(OPEX!$F$30:$BY$30,1,BV$5))} -> -3611.0074 | ... BZ28: {=IF(BZ$5="","",-INDEX(OPEX!$F$30:$BY$30,1,BZ$5))} -> -3611.0074
C29: Non-Capitalized Expenditure | G29: =-'2021 T12'!D139 -> -2926 | H29: =-'2021 T12'!E139 -> 0 | I29: =-'2021 T12'!F139 -> 0 | J29: =-'2021 T12'!G139 -> -2926 | K29: =-'2021 T12'!H139 -> 0 | L29: =-'2021 T12'!I139 -> -1463 | M29: =-'2021 T12'!J139 -> 0 | N29: =-'2021 T12'!K139 -> 0 | ... P29: =-'2021 T12'!M139 -> 0 | Q29: {=IF(Q$5="","",-INDEX(OPEX!$F$31:$BM$31,1,Q$5))} -> 0 | R29: {=IF(R$5="","",-INDEX(OPEX!$F$31:$BM$31,1,R$5))} -> 0 | S29: {=IF(S$5="","",-INDEX(OPEX!$F$31:$BM$31,1,S$5))} -> 0 | T29: {=IF(T$5="","",-INDEX(OPEX!$F$31:$BM$31,1,T$5))} -> 0 | U29: {=IF(U$5="","",-INDEX(OPEX!$F$31:$BM$31,1,U$5))} -> 0 | V29: {=IF(V$5="","",-INDEX(OPEX!$F$31:$BM$31,1,V$5))} -> 0 | W29: {=IF(W$5="","",-INDEX(OPEX!$F$31:$BM$31,1,W$5))} -> 0 | X29: {=IF(X$5="","",-INDEX(OPEX!$F$31:$BM$31,1,X$5))} -> 0 | ... BN29: {=IF(BN$5="","",-INDEX(OPEX!$F$31:$BM$31,1,BN$5))} -> 0 | BO29: {=IF(BO$5="","",-INDEX(OPEX!$F$31:$BY$31,1,BO$5))} -> 0 | BP29: {=IF(BP$5="","",-INDEX(OPEX!$F$31:$BY$31,1,BP$5))} -> 0 | BQ29: {=IF(BQ$5="","",-INDEX(OPEX!$F$31:$BY$31,1,BQ$5))} -> 0 | BR29: {=IF(BR$5="","",-INDEX(OPEX!$F$31:$BY$31,1,BR$5))} -> 0 | BS29: {=IF(BS$5="","",-INDEX(OPEX!$F$31:$BY$31,1,BS$5))} -> 0 | BT29: {=IF(BT$5="","",-INDEX(OPEX!$F$31:$BY$31,1,BT$5))} -> 0 | BU29: {=IF(BU$5="","",-INDEX(OPEX!$F$31:$BY$31,1,BU$5))} -> 0 | BV29: {=IF(BV$5="","",-INDEX(OPEX!$F$31:$BY$31,1,BV$5))} -> 0 | ... BZ29: {=IF(BZ$5="","",-INDEX(OPEX!$F$31:$BY$31,1,BZ$5))} -> 0
C30: Direct Billable Expense | G30: =-'2021 T12'!D147 -> 0 | H30: =-'2021 T12'!E147 -> 0 | I30: =-'2021 T12'!F147 -> 0 | J30: =-'2021 T12'!G147 -> 0 | K30: =-'2021 T12'!H147 -> 0 | L30: =-'2021 T12'!I147 -> -566.57 | M30: =-'2021 T12'!J147 -> 0 | N30: =-'2021 T12'!K147 -> 0 | ... P30: =-'2021 T12'!M147 -> 0 | Q30: {=IF(Q$5="","",-INDEX(OPEX!$F$32:$BM$32,1,Q$5))} -> -209.25 | R30: {=IF(R$5="","",-INDEX(OPEX!$F$32:$BM$32,1,R$5))} -> -209.25 | S30: {=IF(S$5="","",-INDEX(OPEX!$F$32:$BM$32,1,S$5))} -> -209.25 | T30: {=IF(T$5="","",-INDEX(OPEX!$F$32:$BM$32,1,T$5))} -> -209.25 | U30: {=IF(U$5="","",-INDEX(OPEX!$F$32:$BM$32,1,U$5))} -> -209.25 | V30: {=IF(V$5="","",-INDEX(OPEX!$F$32:$BM$32,1,V$5))} -> -209.25 | W30: {=IF(W$5="","",-INDEX(OPEX!$F$32:$BM$32,1,W$5))} -> -209.25 | X30: {=IF(X$5="","",-INDEX(OPEX!$F$32:$BM$32,1,X$5))} -> -209.25 | ... BN30: {=IF(BN$5="","",-INDEX(OPEX!$F$32:$BM$32,1,BN$5))} -> -228.65312 | BO30: {=IF(BO$5="","",-INDEX(OPEX!$F$32:$BY$32,1,BO$5))} -> -235.51272 | BP30: {=IF(BP$5="","",-INDEX(OPEX!$F$32:$BY$32,1,BP$5))} -> -235.51272 | BQ30: {=IF(BQ$5="","",-INDEX(OPEX!$F$32:$BY$32,1,BQ$5))} -> -235.51272 | BR30: {=IF(BR$5="","",-INDEX(OPEX!$F$32:$BY$32,1,BR$5))} -> -235.51272 | BS30: {=IF(BS$5="","",-INDEX(OPEX!$F$32:$BY$32,1,BS$5))} -> -235.51272 | BT30: {=IF(BT$5="","",-INDEX(OPEX!$F$32:$BY$32,1,BT$5))} -> -235.51272 | BU30: {=IF(BU$5="","",-INDEX(OPEX!$F$32:$BY$32,1,BU$5))} -> -235.51272 | BV30: {=IF(BV$5="","",-INDEX(OPEX!$F$32:$BY$32,1,BV$5))} -> -235.51272 | ... BZ30: {=IF(BZ$5="","",-INDEX(OPEX!$F$32:$BY$32,1,BZ$5))} -> -235.51272
C31: Total Operating Expenses | G31: =SUM(G21:G30) -> -108783.56 | H31: =SUM(H21:H30) -> -115321.95 | I31: =SUM(I21:I30) -> -159768.64 | J31: =SUM(J21:J30) -> -65522.72 | K31: =SUM(K21:K30) -> -151531.92 | L31: =SUM(L21:L30) -> -175142.66 | M31: =SUM(M21:M30) -> -131083.81 | N31: =SUM(N21:N30) -> -84586.67 | ... BZ31: =SUM(BZ21:BZ30) -> -123275.95
C33: Net Operating Income | G33: =SUM(G18,G31) -> 128683.09 | H33: =SUM(H18,H31) -> 122144.7 | I33: =SUM(I18,I31) -> 77878.907 | J33: =SUM(J18,J31) -> 172827.88 | K33: =SUM(K18,K31) -> 87078.237 | L33: =SUM(L18,L31) -> 64315.027 | M33: =SUM(M18,M31) -> 108373.88 | N33: =SUM(N18,N31) -> 155237.47 | ... BZ33: =SUM(BZ18,BZ31) -> 216694.65
C35: LEASING & CAPITAL COSTS
C36: Tenant Improvements | G36: {=IF(G$5="","",INDEX('Lease Roll Over'!$N$63:$CK$63,1,G$5))} -> 0 | H36: {=IF(H$5="","",INDEX('Lease Roll Over'!$N$63:$CK$63,1,H$5))} -> 0 | I36: {=IF(I$5="","",INDEX('Lease Roll Over'!$N$63:$CK$63,1,I$5))} -> 0 | J36: {=IF(J$5="","",INDEX('Lease Roll Over'!$N$63:$CK$63,1,J$5))} -> 0 | K36: {=IF(K$5="","",INDEX('Lease Roll Over'!$N$63:$CK$63,1,K$5))} -> 0 | L36: {=IF(L$5="","",INDEX('Lease Roll Over'!$N$63:$CK$63,1,L$5))} -> 0 | M36: {=IF(M$5="","",INDEX('Lease Roll Over'!$N$63:$CK$63,1,M$5))} -> 0 | N36: {=IF(N$5="","",INDEX('Lease Roll Over'!$N$63:$CK$63,1,N$5))} -> 0 | ... BZ36: {=IF(BZ$5="","",INDEX('Lease Roll Over'!$N$63:$CK$63,1,BZ$5))} -> -165000
C37: Leasing Commissions | G37: {=IF(G$5="","",INDEX('Lease Roll Over'!$N$64:$CK$64,1,G$5))} -> 0 | H37: {=IF(H$5="","",INDEX('Lease Roll Over'!$N$64:$CK$64,1,H$5))} -> 0 | I37: {=IF(I$5="","",INDEX('Lease Roll Over'!$N$64:$CK$64,1,I$5))} -> 0 | J37: {=IF(J$5="","",INDEX('Lease Roll Over'!$N$64:$CK$64,1,J$5))} -> 0 | K37: {=IF(K$5="","",INDEX('Lease Roll Over'!$N$64:$CK$64,1,K$5))} -> 0 | L37: {=IF(L$5="","",INDEX('Lease Roll Over'!$N$64:$CK$64,1,L$5))} -> 0 | M37: {=IF(M$5="","",INDEX('Lease Roll Over'!$N$64:$CK$64,1,M$5))} -> 0 | N37: {=IF(N$5="","",INDEX('Lease Roll Over'!$N$64:$CK$64,1,N$5))} -> 0 | ... BZ37: {=IF(BZ$5="","",INDEX('Lease Roll Over'!$N$64:$CK$64,1,BZ$5))} -> -25018.772
C38: Total Leasing & Capital Costs | G38: =SUM(G36:G37) -> 0 | H38: =SUM(H36:H37) -> 0 | I38: =SUM(I36:I37) -> 0 | J38: =SUM(J36:J37) -> 0 | K38: =SUM(K36:K37) -> 0 | L38: =SUM(L36:L37) -> 0 | M38: =SUM(M36:M37) -> 0 | N38: =SUM(N36:N37) -> 0 | ... BZ38: =SUM(BZ36:BZ37) -> -190018.77
C40: Net Cash Flow Before Debt Payment | G40: =SUM(G33,G38) -> 128683.09 | H40: =SUM(H33,H38) -> 122144.7 | I40: =SUM(I33,I38) -> 77878.907 | J40: =SUM(J33,J38) -> 172827.88 | K40: =SUM(K33,K38) -> 87078.237 | L40: =SUM(L33,L38) -> 64315.027 | M40: =SUM(M33,M38) -> 108373.88 | N40: =SUM(N33,N38) -> 155237.47 | ... BZ40: =SUM(BZ33,BZ38) -> 26675.88
C42: SOURCE CHECKS
C43: Rent Check vs. Lease Roll Over | G43: {=G11-INDEX('Lease Roll Over'!$N$62:$CK$62,1,G$5)} -> 88655 | H43: {=H11-INDEX('Lease Roll Over'!$N$62:$CK$62,1,H$5)} -> 88655 | I43: {=I11-INDEX('Lease Roll Over'!$N$62:$CK$62,1,I$5)} -> 88655 | J43: {=J11-INDEX('Lease Roll Over'!$N$62:$CK$62,1,J$5)} -> 88655 | K43: {=K11-INDEX('Lease Roll Over'!$N$62:$CK$62,1,K$5)} -> 88655 | L43: {=L11-INDEX('Lease Roll Over'!$N$62:$CK$62,1,L$5)} -> 88655 | M43: {=M11-INDEX('Lease Roll Over'!$N$62:$CK$62,1,M$5)} -> 88655 | N43: {=N11-INDEX('Lease Roll Over'!$N$62:$CK$62,1,N$5)} -> 88655 | ... BZ43: {=BZ11-INDEX('Lease Roll Over'!$N$62:$CK$62,1,BZ$5)} -> 20439.449
C44: OPEX Check vs. OPEX Tab | G44: {=G31+INDEX(OPEX!$F$33:$BM$33,1,G$5)} -> -587.68708 | H44: {=H31+INDEX(OPEX!$F$33:$BM$33,1,H$5)} -> -7126.0771 | I44: {=I31+INDEX(OPEX!$F$33:$BM$33,1,I$5)} -> -51572.767 | J44: {=J31+INDEX(OPEX!$F$33:$BM$33,1,J$5)} -> 42673.153 | K44: {=K31+INDEX(OPEX!$F$33:$BM$33,1,K$5)} -> -43336.047 | L44: {=L31+INDEX(OPEX!$F$33:$BM$33,1,L$5)} -> -66946.787 | M44: {=M31+INDEX(OPEX!$F$33:$BM$33,1,M$5)} -> -22887.937 | N44: {=N31+INDEX(OPEX!$F$33:$BM$33,1,N$5)} -> 23609.203 | ... BN44: {=BN31+INDEX(OPEX!$F$33:$BM$33,1,BN$5)} -> -10156.303 | BO44: {=BO31+INDEX(OPEX!$F$33:$BY$33,1,BO$5)} -> -13746.865 | BP44: {=BP31+INDEX(OPEX!$F$33:$BY$33,1,BP$5)} -> -13746.865 | BQ44: {=BQ31+INDEX(OPEX!$F$33:$BY$33,1,BQ$5)} -> -13746.865 | BR44: {=BR31+INDEX(OPEX!$F$33:$BY$33,1,BR$5)} -> -13746.865 | BS44: {=BS31+INDEX(OPEX!$F$33:$BY$33,1,BS$5)} -> -13746.865 | BT44: {=BT31+INDEX(OPEX!$F$33:$BY$33,1,BT$5)} -> -13746.865 | BU44: {=BU31+INDEX(OPEX!$F$33:$BY$33,1,BU$5)} -> -13746.865 | BV44: {=BV31+INDEX(OPEX!$F$33:$BY$33,1,BV$5)} -> -13746.865 | ... BZ44: {=BZ31+INDEX(OPEX!$F$33:$BY$33,1,BZ$5)} -> -13746.865
C45: TI Check vs. Lease Roll Over | G45: {=G36-INDEX('Lease Roll Over'!$N$63:$CK$63,1,G$5)} -> 0 | H45: {=H36-INDEX('Lease Roll Over'!$N$63:$CK$63,1,H$5)} -> 0 | I45: {=I36-INDEX('Lease Roll Over'!$N$63:$CK$63,1,I$5)} -> 0 | J45: {=J36-INDEX('Lease Roll Over'!$N$63:$CK$63,1,J$5)} -> 0 | K45: {=K36-INDEX('Lease Roll Over'!$N$63:$CK$63,1,K$5)} -> 0 | L45: {=L36-INDEX('Lease Roll Over'!$N$63:$CK$63,1,L$5)} -> 0 | M45: {=M36-INDEX('Lease Roll Over'!$N$63:$CK$63,1,M$5)} -> 0 | N45: {=N36-INDEX('Lease Roll Over'!$N$63:$CK$63,1,N$5)} -> 0 | ... BZ45: {=BZ36-INDEX('Lease Roll Over'!$N$63:$CK$63,1,BZ$5)} -> 0
C46: LC Check vs. Lease Roll Over | G46: {=G37-INDEX('Lease Roll Over'!$N$64:$CK$64,1,G$5)} -> 0 | H46: {=H37-INDEX('Lease Roll Over'!$N$64:$CK$64,1,H$5)} -> 0 | I46: {=I37-INDEX('Lease Roll Over'!$N$64:$CK$64,1,I$5)} -> 0 | J46: {=J37-INDEX('Lease Roll Over'!$N$64:$CK$64,1,J$5)} -> 0 | K46: {=K37-INDEX('Lease Roll Over'!$N$64:$CK$64,1,K$5)} -> 0 | L46: {=L37-INDEX('Lease Roll Over'!$N$64:$CK$64,1,L$5)} -> 0 | M46: {=M37-INDEX('Lease Roll Over'!$N$64:$CK$64,1,M$5)} -> 0 | N46: {=N37-INDEX('Lease Roll Over'!$N$64:$CK$64,1,N$5)} -> 0 | ... BZ46: {=BZ37-INDEX('Lease Roll Over'!$N$64:$CK$64,1,BZ$5)} -> 0
C48: Occupancy Summary
C49: Occupied SF
...

Sheet Lease Roll Over
B2: Lease Summary
B4: Escalation | C4: 0.03 | L4: Year | M4: 0 | N4: =IF(N5="","",ROUNDUP(N5/12,0)) -> 1 | O4: =IF(O5="","",ROUNDUP(O5/12,0)) -> 1 | P4: =IF(P5="","",ROUNDUP(P5/12,0)) -> 1 | Q4: =IF(Q5="","",ROUNDUP(Q5/12,0)) -> 1 | R4: =IF(R5="","",ROUNDUP(R5/12,0)) -> 1 | S4: =IF(S5="","",ROUNDUP(S5/12,0)) -> 1 | T4: =IF(T5="","",ROUNDUP(T5/12,0)) -> 1 | U4: =IF(U5="","",ROUNDUP(U5/12,0)) -> 1 | ... CG4: =IF(CG5="","",ROUNDUP(CG5/12,0)) -> 6
